Workbook

Sheet 周报
A1: 宏源期货启后私享1号FOF
A2: 产品净值报告
A3: 45961
A4: 估值日期 | B4: 单位净值 | C4: 累计单位净值 | D4: 周涨跌幅 | E4: 沪深300涨跌幅
A5: =启后私享1号FOF周净值!A3 -> 45460 | B5: =启后私享1号FOF周净值!B3 -> 1 | C5: =启后私享1号FOF周净值!C3 -> 1 | D5: =启后私享1号FOF周净值!D3 -> - | E5: =启后私享1号FOF周净值!E3 -> -
A6: =启后私享1号FOF周净值!A4 -> 45464 | B6: =启后私享1号FOF周净值!B4 -> 1.0004 | C6: =启后私享1号FOF周净值!C4 -> 1.0004 | D6: =启后私享1号FOF周净值!D4 -> 0.0004 | E6: =启后私享1号FOF周净值!E4 -> -0.011475595
A7: =启后私享1号FOF周净值!A5 -> 45471 | B7: =启后私享1号FOF周净值!B5 -> 1.0013 | C7: =启后私享1号FOF周净值!C5 -> 1.0013 | D7: =启后私享1号FOF周净值!D5 -> 0.00089964014 | E7: =启后私享1号FOF周净值!E5 -> -0.0097150148
A8: =启后私享1号FOF周净值!A6 -> 45478 | B8: =启后私享1号FOF周净值!B6 -> 1.0023 | C8: =启后私享1号FOF周净值!C6 -> 1.0023 | D8: =启后私享1号FOF周净值!D6 -> 0.00099870169 | E8: =启后私享1号FOF周净值!E6 -> -0.0088396896
A9: =启后私享1号FOF周净值!A7 -> 45485 | B9: =启后私享1号FOF周净值!B7 -> 1.0028 | C9: =启后私享1号FOF周净值!C7 -> 1.0028 | D9: =启后私享1号FOF周净值!D7 -> 0.00049885264 | E9: =启后私享1号FOF周净值!E7 -> 0.012049163
A10: 45492 | B10: 1.004 | C10: 1.004 | D10: =启后私享1号FOF周净值!D8 -> 0.0011966494 | E10: =启后私享1号FOF周净值!E8 -> 0.0191839
A11: 45499 | B11: 1.0058 | C11: 1.0058 | D11: =启后私享1号FOF周净值!D9 -> 0.0017928287 | E11: =启后私享1号FOF周净值!E9 -> -0.036655843
A12: 45506 | B12: 1.006 | C12: 1.006 | D12: =启后私享1号FOF周净值!D10 -> 0.00019884669 | E12: =启后私享1号FOF周净值!E10 -> -0.0073035735
A13: 45513 | B13: 1.0111 | C13: 1.0111 | D13: =启后私享1号FOF周净值!D11 -> 0.0050695825 | E13: =启后私享1号FOF周净值!E11 -> -0.015592175
A14: 45520 | B14: 1.0113 | C14: 1.0113 | D14: =启后私享1号FOF周净值!D12 -> 0.00019780437 | E14: =启后私享1号FOF周净值!E12 -> 0.0042051615
A15: 45527 | B15: 1.0116 | C15: 1.0116 | D15: =启后私享1号FOF周净值!D13 -> 0.00029664788 | E15: =启后私享1号FOF周净值!E13 -> -0.005511518
A16: 45534 | B16: 1.0116 | C16: 1.0116 | D16: =启后私享1号FOF周净值!D14 -> 0 | E16: =启后私享1号FOF周净值!E14 -> -0.0017306493
A17: 45541 | B17: 1.0118 | C17: 1.0118 | D17: =启后私享1号FOF周净值!D15 -> 0.0001977066 | E17: =启后私享1号FOF周净值!E15 -> -0.027121522
A18: 45548 | B18: 1.0109 | C18: 1.0109 | D18: =启后私享1号FOF周净值!D16 -> -0.00088950385 | E18: =启后私享1号FOF周净值!E16 -> -0.02231575
A19: 45555 | B19: 1.0097 | C19: 1.0097 | D19: =启后私享1号FOF周净值!D17 -> -0.001187061 | E19: =启后私享1号FOF周净值!E17 -> 0.013234101
A20: 45562 | B20: 1.0139 | C20: 1.0139 | D20: =启后私享1号FOF周净值!D18 -> 0.0041596514 | E20: =启后私享1号FOF周净值!E18 -> 0.15702199
A21: 45565 | B21: 1.0181 | C21: 1.0181 | D21: =启后私享1号FOF周净值!D19 -> 0.0041424204 | E21: =启后私享1号FOF周净值!E19 -> 0.084826223
... A76: 45961 | B76: 1.112 | C76: 1.112 | D76: =启后私享1号FOF周净值!D74 -> 0.0036101083 | E76: =启后私享1号FOF周净值!E74 -> -0.0042933649
F77: 区间收益表
F78: 数据区间 | H78: 最近一周 | I78: 最近一月 | J78: 最近三月 | K78: 成立以来
K79: 收益率 | L79: 年化
F81: 启后私享1号FOF | H81: -0.0006 | I81: 0.0027 | J81: 0.0098 | K81: 0.112 | L81: 0.0804
F83: 基金简介
F84: 成立日期 | H84: 45460
F85: 产品类型 | H85: 期货和衍生品类FOF
F86: 基金经理 | H86: 廖永国
F87: 最大回撤 | H87: 0.0029
F88: 预警/止损 | H88: 止损0.5
F89: 费率 | H89: 管理费0.15%/年，托管+外包费0.2%/年
F90: 业绩报酬 | H90: 0
F91: 开放日 | H91: 每周三
E94: 重要声明
A95: 1.本资料中的各种信息和数据等仅供参考，具体以管理人公布净值为准；此数据并不构成销售要约，或买入任何证券、基金或其它投资工具的建议。投资者应仔细审阅相关金融产品的合同文件等以了解其风险因素，或寻求专业的投资顾问的建议。图表数据来源于管理人产品估值计算 2.本材料信息不作为宣传资料向公众散发，不得转或给第三方传阅，不得用于未经允许的其他任何用途。历史业绩不代表未来收益，也不构成产品财产不受损失或取得最低收益的承诺 3.本资料不对投资人的本金和收益作出任何保证，投资人投资本产品仍存在可能导致投资人不能获得收益设置面临本全受损的风险

Sheet 启后私享1号FOF周净值
A1: 1 | B1: 2 | C1: 3 | D1: 4 | E1: 5 | F1: 6 | G1: 7 | H1: 8 | I1: 9 | J1: 10 | K1: 11 | L1: 12 | M1: 13
A2: 估值日期 | B2: 单位净值 | C2: 累计单位净值 | D2: 周涨跌幅 | E2: 沪深300涨跌幅 | F2: 沪深300 | G2: 周回撤 | H2: 最大回撤 | I2: 启后私享1号FOF | J2: 沪深300 | K2: 最大回撤≥5% | L2: 单位净值≤0.95 | M2: 周度收益率跌幅≥2%
A3: 45460 | B3: 1 | C3: 1 | D3: - | E3: - | F3: 3536.2 | I3: =C3 -> 1 | J3: 1
A4: 45464 | B4: 1.0004 | C4: 1.0004 | D4: =IF(A4="","",(B4-B3)/B3) -> 0.0004 | E4: =IF(A4="","",(F4-F3)/F3) -> -0.011475595 | F4: 3495.62 | G4: =IF(A4="","",(MAX(C$4:C4)-C4)/MAX(C$4:C4)) -> 0 | H4: =IF(A4="","",MAX(G$4:G4)) -> 0 | I4: =IF(A4="","",C4) -> 1.0004 | J4: =IF(A4="","",J3*(1+E4)) -> 0.9885244 | K4: =IF(A4="","",IF(H4>5%,"是","否")) -> 否 | L4: =IF(A4="","",IF(B4>0.95,"否","是")) -> 否 | M4: =IF(A4="","",IF(D4<2%,"否","是")) -> 否
A5: 45471 | B5: 1.0013 | C5: 1.0013 | D5: =IF(A5="","",(B5-B4)/B4) -> 0.00089964014 | E5: =IF(A5="","",(F5-F4)/F4) -> -0.0097150148 | F5: 3461.66 | G5: =IF(A5="","",(MAX(C$4:C5)-C5)/MAX(C$4:C5)) -> 0 | H5: =IF(A5="","",MAX(G$4:G5)) -> 0 | I5: =IF(A5="","",C5) -> 1.0013 | J5: =IF(A5="","",J4*(1+E5)) -> 0.97892088 | K5: =IF(A5="","",IF(H5>5%,"是","否")) -> 否 | L5: =IF(A5="","",IF(B5>0.95,"否","是")) -> 否 | M5: =IF(A5="","",IF(D5<2%,"否","是")) -> 否
A6: 45478 | B6: 1.0023 | C6: 1.0023 | D6: =IF(A6="","",(B6-B5)/B5) -> 0.00099870169 | E6: =IF(A6="","",(F6-F5)/F5) -> -0.0088396896 | F6: 3431.06 | G6: =IF(A6="","",(MAX(C$4:C6)-C6)/MAX(C$4:C6)) -> 0 | H6: =IF(A6="","",MAX(G$4:G6)) -> 0 | I6: =IF(A6="","",C6) -> 1.0023 | J6: =IF(A6="","",J5*(1+E6)) -> 0.97026752 | K6: =IF(A6="","",IF(H6>5%,"是","否")) -> 否 | L6: =IF(A6="","",IF(B6>0.95,"否","是")) -> 否 | M6: =IF(A6="","",IF(D6<2%,"否","是")) -> 否
A7: 45485 | B7: 1.0028 | C7: 1.0028 | D7: =IF(A7="","",(B7-B6)/B6) -> 0.00049885264 | E7: =IF(A7="","",(F7-F6)/F6) -> 0.012049163 | F7: 3472.4014 | G7: =IF(A7="","",(MAX(C$4:C7)-C7)/MAX(C$4:C7)) -> 0 | H7: =IF(A7="","",MAX(G$4:G7)) -> 0 | I7: =IF(A7="","",C7) -> 1.0028 | J7: =IF(A7="","",J6*(1+E7)) -> 0.98195843 | K7: =IF(A7="","",IF(H7>5%,"是","否")) -> 否 | L7: =IF(A7="","",IF(B7>0.95,"否","是")) -> 否 | M7: =IF(A7="","",IF(D7<2%,"否","是")) -> 否
A8: 45492 | B8: 1.004 | C8: 1.004 | D8: =IF(A8="","",(B8-B7)/B7) -> 0.0011966494 | E8: =IF(A8="","",(F8-F7)/F7) -> 0.0191839 | F8: 3539.0156 | G8: =IF(A8="","",(MAX(C$4:C8)-C8)/MAX(C$4:C8)) -> 0 | H8: =IF(A8="","",MAX(G$4:G8)) -> 0 | I8: =IF(A8="","",C8) -> 1.004 | J8: =IF(A8="","",J7*(1+E8)) -> 1.0007962 | K8: =IF(A8="","",IF(H8>5%,"是","否")) -> 否 | L8: =IF(A8="","",IF(B8>0.95,"否","是")) -> 否 | M8: =IF(A8="","",IF(D8<2%,"否","是")) -> 否
A9: 45499 | B9: 1.0058 | C9: 1.0058 | D9: =IF(A9="","",(B9-B8)/B8) -> 0.0017928287 | E9: =IF(A9="","",(F9-F8)/F8) -> -0.036655843 | F9: 3409.29 | G9: =IF(A9="","",(MAX(C$4:C9)-C9)/MAX(C$4:C9)) -> 0 | H9: =IF(A9="","",MAX(G$4:G9)) -> 0 | I9: =IF(A9="","",C9) -> 1.0058 | J9: =IF(A9="","",J8*(1+E9)) -> 0.96411119 | K9: =IF(A9="","",IF(H9>5%,"是","否")) -> 否 | L9: =IF(A9="","",IF(B9>0.95,"否","是")) -> 否 | M9: =IF(A9="","",IF(D9<2%,"否","是")) -> 否
A10: 45506 | B10: 1.006 | C10: 1.006 | D10: =IF(A10="","",(B10-B9)/B9) -> 0.00019884669 | E10: =IF(A10="","",(F10-F9)/F9) -> -0.0073035735 | F10: 3384.39 | G10: =IF(A10="","",(MAX(C$4:C10)-C10)/MAX(C$4:C10)) -> 0 | H10: =IF(A10="","",MAX(G$4:G10)) -> 0 | I10: =IF(A10="","",C10) -> 1.006 | J10: =IF(A10="","",J9*(1+E10)) -> 0.95706974 | K10: =IF(A10="","",IF(H10>5%,"是","否")) -> 否 | L10: =IF(A10="","",IF(B10>0.95,"否","是")) -> 否 | M10: =IF(A10="","",IF(D10<2%,"否","是")) -> 否
A11: 45513 | B11: 1.0111 | C11: 1.0111 | D11: =IF(A11="","",(B11-B10)/B10) -> 0.0050695825 | E11: =IF(A11="","",(F11-F10)/F10) -> -0.015592175 | F11: 3331.62 | G11: =IF(A11="","",(MAX(C$4:C11)-C11)/MAX(C$4:C11)) -> 0 | H11: =IF(A11="","",MAX(G$4:G11)) -> 0 | I11: =IF(A11="","",C11) -> 1.0111 | J11: =IF(A11="","",J10*(1+E11)) -> 0.94214694 | K11: =IF(A11="","",IF(H11>5%,"是","否")) -> 否 | L11: =IF(A11="","",IF(B11>0.95,"否","是")) -> 否 | M11: =IF(A11="","",IF(D11<2%,"否","是")) -> 否
A12: 45520 | B12: 1.0113 | C12: 1.0113 | D12: =IF(A12="","",(B12-B11)/B11) -> 0.00019780437 | E12: =IF(A12="","",(F12-F11)/F11) -> 0.0042051615 | F12: 3345.63 | G12: =IF(A12="","",(MAX(C$4:C12)-C12)/MAX(C$4:C12)) -> 0 | H12: =IF(A12="","",MAX(G$4:G12)) -> 0 | I12: =IF(A12="","",C12) -> 1.0113 | J12: =IF(A12="","",J11*(1+E12)) -> 0.94610882 | K12: =IF(A12="","",IF(H12>5%,"是","否")) -> 否 | L12: =IF(A12="","",IF(B12>0.95,"否","是")) -> 否 | M12: =IF(A12="","",IF(D12<2%,"否","是")) -> 否
A13: 45527 | B13: 1.0116 | C13: 1.0116 | D13: =IF(A13="","",(B13-B12)/B12) -> 0.00029664788 | E13: =IF(A13="","",(F13-F12)/F12) -> -0.005511518 | F13: 3327.1905 | G13: =IF(A13="","",(MAX(C$4:C13)-C13)/MAX(C$4:C13)) -> 0 | H13: =IF(A13="","",MAX(G$4:G13)) -> 0 | I13: =IF(A13="","",C13) -> 1.0116 | J13: =IF(A13="","",J12*(1+E13)) -> 0.94089432 | K13: =IF(A13="","",IF(H13>5%,"是","否")) -> 否 | L13: =IF(A13="","",IF(B13>0.95,"否","是")) -> 否 | M13: =IF(A13="","",IF(D13<2%,"否","是")) -> 否
A14: 45534 | B14: 1.0116 | C14: 1.0116 | D14: =IF(A14="","",(B14-B13)/B13) -> 0 | E14: =IF(A14="","",(F14-F13)/F13) -> -0.0017306493 | F14: 3321.4323 | G14: =IF(A14="","",(MAX(C$4:C14)-C14)/MAX(C$4:C14)) -> 0 | H14: =IF(A14="","",MAX(G$4:G14)) -> 0 | I14: =IF(A14="","",C14) -> 1.0116 | J14: =IF(A14="","",J13*(1+E14)) -> 0.93926596 | K14: =IF(A14="","",IF(H14>5%,"是","否")) -> 否 | L14: =IF(A14="","",IF(B14>0.95,"否","是")) -> 否 | M14: =IF(A14="","",IF(D14<2%,"否","是")) -> 否
A15: 45541 | B15: 1.0118 | C15: 1.0118 | D15: =IF(A15="","",(B15-B14)/B14) -> 0.0001977066 | E15: =IF(A15="","",(F15-F14)/F14) -> -0.027121522 | F15: 3231.35 | G15: =IF(A15="","",(MAX(C$4:C15)-C15)/MAX(C$4:C15)) -> 0 | H15: =IF(A15="","",MAX(G$4:G15)) -> 0 | I15: =IF(A15="","",C15) -> 1.0118 | J15: =IF(A15="","",J14*(1+E15)) -> 0.91379164 | K15: =IF(A15="","",IF(H15>5%,"是","否")) -> 否 | L15: =IF(A15="","",IF(B15>0.95,"否","是")) -> 否 | M15: =IF(A15="","",IF(D15<2%,"否","是")) -> 否
... A73: 45954 | B73: 1.1126 | C73: 1.1126 | D73: =IF(A73="","",(B73-B72)/B72) -> 0.0016204537 | E73: =IF(A73="","",(F73-F72)/F72) -> 0.032441856 | F73: 4660.68 | G73: =IF(A73="","",(MAX(C$4:C73)-C73)/MAX(C$4:C73)) -> 0 | H73: =IF(A73="","",MAX(G$4:G73)) -> 0.0028880866 | I73: =IF(A73="","",C73) -> 1.1126 | J73: =IF(A73="","",J72*(1+E73)) -> 1.3179911 | K73: =IF(A73="","",IF(H73>5%,"是","否")) -> 否 | L73: =IF(A73="","",IF(B73>0.95,"否","是")) -> 否 | M73: =IF(A73="","",IF(D73<2%,"否","是")) -> 否
A74: 45961 | B74: 1.112 | C74: 1.112 | D74: =IF(A74="","",(B74-B65)/B65) -> 0.0036101083 | E74: =IF(A74="","",(F74-F73)/F73) -> -0.0042933649 | F74: 4640.67 | G74: =IF(A74="","",(MAX(C$4:C74)-C74)/MAX(C$4:C74)) -> 0.00053927737 | H74: =IF(A74="","",MAX(G$4:G74)) -> 0.0028880866 | I74: =IF(A74="","",C74) -> 1.112 | J74: =IF(A74="","",J65*(1+E74)) -> 1.2327367 | K74: =IF(A74="","",IF(H74>5%,"是","否")) -> 否 | L74: =IF(A74="","",IF(B74>0.95,"否","是")) -> 否 | M74: =IF(A74="","",IF(D74<2%,"否","是")) -> 否
D75: =IF(A75="","",(B75-B74)/B74) | E75: =IF(A75="","",(F75-F74)/F74) | G75: =IF(A75="","",(MAX(C$4:C75)-C75)/MAX(C$4:C75)) | H75: =IF(A75="","",MAX(G$4:G75)) | I75: =IF(A75="","",C75) | J75: =IF(A75="","",J74*(1+E75)) | K75: =IF(A75="","",IF(H75>5%,"是","否")) | L75: =IF(A75="","",IF(B75>0.95,"否","是")) | M75: =IF(A75="","",IF(D75<2%,"否","是"))
D76: =IF(A76="","",(B76-B75)/B75) | E76: =IF(A76="","",(F76-F75)/F75) | G76: =IF(A76="","",(MAX(C$4:C76)-C76)/MAX(C$4:C76)) | H76: =IF(A76="","",MAX(G$4:G76)) | I76: =IF(A76="","",C76) | J76: =IF(A76="","",J75*(1+E76)) | K76: =IF(A76="","",IF(H76>5%,"是","否")) | L76: =IF(A76="","",IF(B76>0.95,"否","是")) | M76: =IF(A76="","",IF(D76<2%,"否","是"))
D77: =IF(A77="","",(B77-B76)/B76) | E77: =IF(A77="","",(F77-F76)/F76) | G77: =IF(A77="","",(MAX(C$4:C77)-C77)/MAX(C$4:C77)) | H77: =IF(A77="","",MAX(G$4:G77)) | I77: =IF(A77="","",C77) | J77: =IF(A77="","",J76*(1+E77)) | K77: =IF(A77="","",IF(H77>5%,"是","否")) | L77: =IF(A77="","",IF(B77>0.95,"否","是")) | M77: =IF(A77="","",IF(D77<2%,"否","是"))
D78: =IF(A78="","",(B78-B77)/B77) | E78: =IF(A78="","",(F78-F77)/F77) | G78: =IF(A78="","",(MAX(C$4:C78)-C78)/MAX(C$4:C78)) | H78: =IF(A78="","",MAX(G$4:G78)) | I78: =IF(A78="","",C78) | J78: =IF(A78="","",J77*(1+E78)) | K78: =IF(A78="","",IF(H78>5%,"是","否")) | L78: =IF(A78="","",IF(B78>0.95,"否","是")) | M78: =IF(A78="","",IF(D78<2%,"否","是"))
D79: =IF(A79="","",(B79-B78)/B78) | E79: =IF(A79="","",(F79-F78)/F78) | G79: =IF(A79="","",(MAX(C$4:C79)-C79)/MAX(C$4:C79)) | H79: =IF(A79="","",MAX(G$4:G79)) | I79: =IF(A79="","",C79) | J79: =IF(A79="","",J78*(1+E79)) | K79: =IF(A79="","",IF(H79>5%,"是","否")) | L79: =IF(A79="","",IF(B79>0.95,"否","是")) | M79: =IF(A79="","",IF(D79<2%,"否","是"))
D80: =IF(A80="","",(B80-B79)/B79) | E80: =IF(A80="","",(F80-F79)/F79) | G80: =IF(A80="","",(MAX(C$4:C80)-C80)/MAX(C$4:C80)) | H80: =IF(A80="","",MAX(G$4:G80)) | I80: =IF(A80="","",C80) | J80: =IF(A80="","",J79*(1+E80)) | K80: =IF(A80="","",IF(H80>5%,"是","否")) | L80: =IF(A80="","",IF(B80>0.95,"否","是")) | M80: =IF(A80="","",IF(D80<2%,"否","是"))
D81: =IF(A81="","",(B81-B80)/B80) | E81: =IF(A81="","",(F81-F80)/F80) | G81: =IF(A81="","",(MAX(C$4:C81)-C81)/MAX(C$4:C81)) | H81: =IF(A81="","",MAX(G$4:G81)) | I81: =IF(A81="","",C81) | J81: =IF(A81="","",J80*(1+E81)) | K81: =IF(A81="","",IF(H81>5%,"是","否")) | L81: =IF(A81="","",IF(B81>0.95,"否","是")) | M81: =IF(A81="","",IF(D81<2%,"否","是"))
D82: =IF(A82="","",(B82-B81)/B81) | E82: =IF(A82="","",(F82-F81)/F81) | G82: =IF(A82="","",(MAX(C$4:C82)-C82)/MAX(C$4:C82)) | H82: =IF(A82="","",MAX(G$4:G82)) | I82: =IF(A82="","",C82) | J82: =IF(A82="","",J81*(1+E82)) | K82: =IF(A82="","",IF(H82>5%,"是","否")) | L82: =IF(A82="","",IF(B82>0.95,"否","是")) | M82: =IF(A82="","",IF(D82<2%,"否","是"))
D83: =IF(A83="","",(B83-B82)/B82) | E83: =IF(A83="","",(F83-F82)/F82) | G83: =IF(A83="","",(MAX(C$4:C83)-C83)/MAX(C$4:C83)) | H83: =IF(A83="","",MAX(G$4:G83)) | I83: =IF(A83="","",C83) | J83: =IF(A83="","",J82*(1+E83)) | K83: =IF(A83="","",IF(H83>5%,"是","否")) | L83: =IF(A83="","",IF(B83>0.95,"否","是")) | M83: =IF(A83="","",IF(D83<2%,"否","是"))
D84: =IF(A84="","",(B84-B83)/B83) | E84: =IF(A84="","",(F84-F83)/F83) | G84: =IF(A84="","",(MAX(C$4:C84)-C84)/MAX(C$4:C84)) | H84: =IF(A84="","",MAX(G$4:G84)) | I84: =IF(A84="","",C84) | J84: =IF(A84="","",J83*(1+E84)) | K84: =IF(A84="","",IF(H84>5%,"是","否")) | L84: =IF(A84="","",IF(B84>0.95,"否","是")) | M84: =IF(A84="","",IF(D84<2%,"否","是"))
D85: =IF(A85="","",(B85-B84)/B84) | E85: =IF(A85="","",(F85-F84)/F84) | G85: =IF(A85="","",(MAX(C$4:C85)-C85)/MAX(C$4:C85)) | H85: =IF(A85="","",MAX(G$4:G85)) | I85: =IF(A85="","",C85) | J85: =IF(A85="","",J84*(1+E85)) | K85: =IF(A85="","",IF(H85>5%,"是","否")) | L85: =IF(A85="","",IF(B85>0.95,"否","是")) | M85: =IF(A85="","",IF(D85<2%,"否","是"))
D86: =IF(A86="","",(B86-B85)/B85) | E86: =IF(A86="","",(F86-F85)/F85) | G86: =IF(A86="","",(MAX(C$4:C86)-C86)/MAX(C$4:C86)) | H86: =IF(A86="","",MAX(G$4:G86)) | I86: =IF(A86="","",C86) | J86: =IF(A86="","",J85*(1+E86)) | K86: =IF(A86="","",IF(H86>5%,"是","否")) | L86: =IF(A86="","",IF(B86>0.95,"否","是")) | M86: =IF(A86="","",IF(D86<2%,"否","是"))
... D361: =IF(A361="","",(B361-B360)/B360) | E361: =IF(A361="","",(F361-F360)/F360) | G361: =IF(A361="","",(MAX(C$4:C361)-C361)/MAX(C$4:C361)) | H361: =IF(A361="","",MAX(G$4:G361)) | I361: =IF(A361="","",C361) | J361: =IF(A361="","",J360*(1+E361)) | K361: =IF(A361="","",IF(H361>5%,"是","否")) | L361: =IF(A361="","",IF(B361>0.95,"否","是")) | M361: =IF(A361="","",IF(D361<2%,"否","是"))

Sheet 子基金及业绩基准周净值
A1: 1 | B1: 2 | C1: 3 | D1: 4 | E1: 5 | F1: 6 | G1: 7 | H1: 8 | I1: 9 | J1: 10 | K1: 11 | L1: 12 | M1: 13 | N1: 14 | O1: 15 | P1: 16 | Q1: 17 | R1: 18 | S1: 19 | T1: 20 | U1: 21 | V1: 22 | W1: 23 | X1: 24 | Y1: 25 | Z1: 26 | AA1: 27 | AB1: 28 | AC1: 29 | AD1: 30 | AE1: 31 | AF1: 32 | AG1: 注：子基金净值为体现在FOF估值表上的市价（虚拟净值）
A2: 估值日期 | B2: 鸣石量化24号 | C2: 盛冠达量化套利6号 | D2: 因诺期权1号 | E2: 正瀛骐骥21号 | F2: 致远量化对冲运作6号 | G2: 磐松市场中性2号 | H2: 量游鸿雁8号 | I2: 子午中性16号 | J2: 世纪前沿松柏量化对冲6号 | K2: 瀛岳核心 | L2: 创世纪顾锝群英8号 | M2: 艮岳康柏1号 | N2: 哲萌龙泉进取2号 | O2: 德贝尊享CTA8号 | P2: 锡和骐骥1号 | Q2: 特夫郁金香弦理1号 | R2: 交叉智能-量化套利2号 | S2: 交叉智能启航1号 | T2: 鸣石CTA套利1号 | U2: 创世纪顾锝屠龙1号 | V2: 远澜藤枫6号 | W2: 悦海盈和18号 | X2: 玄元元中10号 | Y2: 玄元元中12号 | Z2: 磐松多空对冲5号 | AA2: 量子智盈6号 | AB2: 垒昂金鹿13号 | AC2: 悦海盈和12号 | AD2: 因诺天跃19号 | AE2: 念觉500指增稳健Plus27号 | AF2: 天算指增保护6号 | AG2: 朝阳永续股票市场中性细分策略指数 | AH2: 朝阳永续套利策略宽基指数 | AI2: 打板拟合指数（打板+0.2*炸板）*0.2 | AJ2: 万得可转债等权（889033.WI）（周涨跌幅） | AK2: 宏观策略拟合指数（周涨跌幅） | AL2: 朝阳永续灵活对冲指数（周涨跌幅） | AM2: 朝阳永续1000指增细分策略指数
A3: 45469 | B3: 1.0494 | C3: 1.386
A4: 45471 | B4: 1.051 | C4: 1.386 | AG4: 1991.1394
A5: 45478 | B5: 1.0518 | C5: 1.387 | D5: 1.3759 | AG5: 1906.6949 | AH5: 2475.0671
A6: 45485 | B6: 1.0527 | C6: 1.385 | D6: 1.3786 | AG6: 1907.2442 | AH6: 2477.9758
A7: 45492 | B7: 1.0536 | C7: 1.386 | D7: 1.3823 | E7: 1.0227 | AG7: 1898.121 | AH7: 2475.8544
A8: 45499 | B8: 1.0585 | C8: 1.388 | D8: 1.3807 | E8: 1.0234 | AG8: 1898.1919 | AH8: 2468.5907
A9: 45506 | B9: 1.0615 | C9: 1.385 | D9: 1.3806 | E9: 1.0188 | AG9: 1898.171 | AH9: 2468.8505
A10: 45513 | B10: 1.0762 | C10: 1.388 | D10: 1.3778 | E10: 1.0195 | AG10: 1890.9012 | AH10: 2463.1697
A11: 45520 | B11: 1.0767 | C11: 1.388 | D11: 1.3774 | E11: 1.0205 | AG11: 1990.9192 | AH11: 2471.9122
A12: 45527 | B12: 1.0783 | C12: 1.388 | D12: 1.376 | E12: 1.0204 | AG12: 1896.9679 | AH12: 2469.6998
A13: 45534 | B13: 1.078 | C13: 1.391 | D13: 1.3766 | E13: 1.0173 | AG13: 1891.1312 | AH13: 2472.3681
A14: 45541 | B14: 1.0775 | C14: 1.389 | D14: 1.3771 | E14: 1.0217 | AG14: 1892.5221 | AH14: 2468.7615
A15: 45548 | B15: 1.0757 | C15: 1.39 | D15: 1.3753 | E15: 1.0213 | AG15: 1965.7205 | AH15: 2464.0527
A16: 45555 | B16: 1.0718 | C16: 1.389 | D16: 1.3748 | E16: 1.0254 | AG16: 1970.6754 | AH16: 2462.8354
A17: 45562 | B17: 1.0705 | C17: 1.406 | D17: 1.4032 | E17: 1.0016 | AG17: 1936.1795 | AH17: 2460.9337
A18: 45565 | B18: 1.0662 | C18: 1.409 | D18: 1.4354 | E18: 0.9982 | AG18: 1956.9334 | AH18: 2480.3431
A19: 45576 | B19: 1.074246 | C19: 1.4162 | D19: 1.441 | E19: 1.0363 | F19: 1.0314 | AG19: 1968.446 | AH19: 2496.6067
A20: 45583 | B20: 1.079986 | C20: 1.4178 | D20: 1.4585 | E20: 1.0327 | F20: 1.0153 | AG20: 1962.9914 | AH20: 2497.0735
A21: 45590 | B21: 1.077116 | C21: 1.4194 | D21: 1.4599 | E21: 1.0387 | F21: 1.0287 | G21: 1.0458 | H21: 1.0766 | I21: 1.0902 | J21: 0.9951 | AG21: 1987.3681 | AH21: 2512.9154
A22: 45597 | B22: 1.081298 | C22: 1.421 | D22: 1.4638 | E22: 1.0398 | F22: 1.0225 | G22: 1.0373 | H22: 1.0753 | I22: 1.09428 | J22: 0.9974 | AG22: 1982.0559 | AH22: 2516.4288
A23: 45604 | B23: 1.107374 | C23: 1.417 | D23: 1.4682 | E23: 1.041 | F23: 1.0179 | G23: 1.0439 | H23: 1.0753 | I23: 1.10068 | J23: 0.9976 | AG23: 2003.0979 | AH23: 2543.3126
A24: 45611 | B24: 1.117378 | C24: 1.4122 | D24: 1.4727 | E24: 1.0422 | F24: 1.0189 | G24: 1.0389 | H24: 1.0867 | I24: 1.09868 | J24: 0.9942 | AG24: 2005.0707 | AH24: 2543.7176
A25: 45618 | B25: 1.1191 | C25: 1.4098 | D25: 1.4759 | E25: 1.0434 | F25: 1.0289 | G25: 1.0473 | H25: 1.0901 | I25: 1.10556 | J25: 1.0012 | AG25: 2022.2224 | AH25: 2545.1616
A26: 45625 | B26: 1.117296 | C26: 1.4106 | D26: 1.4877 | E26: 1.0445 | F26: 1.0351 | G26: 1.0609 | H26: 1.0915 | I26: 1.10908 | J26: 1.0058 | AG26: 2041.7648 | AH26: 2555.2175
A27: 45632 | B27: 1.11213 | C27: 1.4106 | D27: 1.49 | E27: 1.0457 | F27: 1.0378 | G27: 1.0644 | H27: 1.0901 | I27: 1.11268 | J27: 1.0113 | AG27: 2059.9262 | AH27: 2564.2629
A28: 45639 | B28: 1.124594 | C28: 1.4106 | D28: 1.4958 | E28: 1.0469 | F28: 1.0407 | G28: 1.0722 | H28: 1.0917 | I28: 1.11708 | J28: 1.0171 | K28: 1.6066 | AG28: 2066.3942 | AH28: 2568.7853 | AI28: 0.0108
A29: 45646 | B29: 1.125086 | C29: 1.4106 | D29: 1.5253 | E29: 1.0481 | F29: 1.0376 | G29: 1.0658 | H29: 1.0984 | I29: 1.11964 | J29: 1.0154 | K29: 1.6171 | AG29: 2068.2326 | AH29: 2569.8461 | AI29: -0.0137
A30: 45653 | B30: 1.122052 | C30: 1.4122 | D30: 1.5286 | E30: 1.0492 | F30: 1.0375 | G30: 1.0636 | H30: 1.1045 | I30: 1.11396 | J30: 1.0177 | K30: 1.6042 | AG30: 2056.8554 | AH30: 2570.0928 | AI30: -0.0053
A31: 45660 | B31: 1.0524 | D31: 1.5327 | E31: 1.0504 | F31: 1.0458 | G31: 1.0606 | H31: 1.0978 | I31: 1.10836 | J31: 1.0189 | K31: 1.5944 | L31: 1.0052 | AG31: 2045.0243 | AH31: 2558.912 | AI31: -0.0094
A32: 45667 | B32: 1.0588 | D32: 1.5446 | E32: 1.0516 | F32: 1.0454 | G32: 1.0617 | H32: 1.0973 | I32: 1.11012 | J32: 1.0201 | K32: 1.6351 | L32: 0.9989 | M32: 0.9031 | AG32: 2052.0449 | AH32: 2559.4037 | AI32: 0.0044
A33: 45674 | B33: 1.0606 | D33: 1.5443 | E33: 1.0528 | F33: 1.0472 | G33: 1.0644 | H33: 1.0969 | I33: 1.11124 | J33: 1.0229 | K33: 1.6292 | L33: 1.0015 | M33: 0.9164 | AG33: 2069.2505 | AH33: 2569.0407 | AI33: 0.0076
A34: 45681 | B34: 1.0609 | D34: 1.5504 | E34: 1.0539 | F34: 1.0444 | G34: 1.0652 | H34: 1.0969 | I34: 1.10876 | J34: 1.0266 | K34: 1.6221 | L34: 1.0011 | M34: 0.924 | N34: 1.0621 | O34: 1.061 | P34: 1.0234 | AG34: 2078.4731 | AH34: 2576.0619 | AI34: -0.0024 | AJ34: 0.0133
A35: 45684 | B35: 1.06447 | D35: 1.5537 | E35: 1.0555 | F35: 1.0502 | G35: 1.0661 | H35: 1.101 | I35: 1.10724 | J35: 1.027 | K35: 1.6213 | L35: 0.9958 | M35: 0.9202 | N35: 1.061 | O35: 1.059 | P35: 1.0325 | AG35: 2078.6747 | AH35: 2576.8476 | AI35: -0.0047 | AJ35: -0.0016
A36: 45695 | B36: 1.0682 | D36: 1.5603 | E36: 1.0563 | F36: 1.0471 | G36: 1.0749 | H36: 1.1021 | I36: 1.119 | J36: 1.0279 | K36: 1.6231 | L36: 0.9993 | M36: 0.9337 | N36: 1.0633 | O36: 1.065 | P36: 1.0335 | AG36: 2092.8097 | AH36: 2583.9932 | AI36: 0.0173 | AJ36: 0.0231
A37: 45702 | B37: 1.07513 | D37: 1.5625 | E37: 1.0575 | F37: 1.043 | G37: 1.0758 | H37: 1.1001 | I37: 1.12668 | J37: 1.0338 | K37: 1.6656 | L37: 1.01087 | M37: 0.9384 | N37: 1.068 | O37: 1.063 | P37: 1.0499 | AG37: 2100.2368 | AH37: 2589.6122 | AI37: 0.0145 | AJ37: 0.0042
A38: 45709 | B38: 1.08128 | D38: 1.5666 | E38: 1.0586 | F38: 1.0368 | G38: 1.0772 | H38: 1.086 | I38: 1.13108 | J38: 1.0409 | K38: 1.6977 | L38: 1.0197679 | M38: 0.9519 | N38: 1.0705 | O38: 1.065 | P38: 1.0521 | AG38: 2107.3377 | AH38: 2604.8592 | AI38: 0.0194 | AJ38: 0.0235
A39: 45716 | B39: 1.090136 | D39: 1.5709 | E39: 1.0598 | F39: 1.0488 | G39: 1.0837 | H39: 1.0919 | I39: 1.13036 | J39: 1.0386 | K39: 1.7133 | L39: 1.0205462 | M39: 0.9444 | N39: 1.0701 | O39: 1.063 | P39: 1.0573 | AG39: 2108.1727 | AH39: 2602.7604 | AI39: 0.0036 | AJ39: -0.0164
A40: 45723 | B40: 1.08579 | D40: 1.5733 | E40: 1.061 | F40: 1.05 | G40: 1.084 | H40: 1.0919 | I40: 1.13716 | J40: 1.0494 | K40: 1.7204 | L40: 1.0282245 | M40: 0.9593 | N40: 1.0712 | O40: 1.058 | P40: 1.0706 | Q40: 1.106 | AG40: 2130.045 | AH40: 2615.1614 | AI40: 0.0099 | AJ40: 0.0215
...

Sheet 业绩归因
A1: 宏源期货启后私享1号FOF | B1: 日期 | C1: =周报!A3 -> 45961 | D1: FOF净资产 | F1: 88841763 | G1: 注：子基金净值为虚拟净值
A2: 业绩归因报告 | B2: 子基金净值 | CB2: 成立日期
B3: 策略 | C3: 子基金 | D3: 市值占净值% | E3: 成本 | F3: 市值 | J3: 45961 | K3: 45954 | L3: 45947 | M3: 45940 | N3: 45926 | O3: 45919 | P3: 45912 | Q3: 45905 | R3: 45898 | S3: 45891 | T3: 45884 | U3: 45877 | V3: 45870 | W3: 45863 | X3: 45856 | Y3: 45849 | Z3: 45842 | AA3: 45835 | AB3: 45828 | AC3: 45821 | AD3: 45814 | AE3: 45807 | AF3: 45800 | AG3: 45793 | AH3: 45786 | AI3: 45772 | AJ3: 45765 | AK3: 45758 | AL3: 45750 | AM3: 45744 | AN3: 45737 | AO3: 45730 | AP3: 45723 | AQ3: 45716 | AR3: 45709 | AS3: 45702 | AT3: 45695 | AU3: 45684 | AV3: 45681 | AW3: 45674 | AX3: 45667 | AY3: 45660 | AZ3: 45653 | BA3: 45646 | BB3: 45639 | BC3: 45632 | BD3: 45625 | BE3: 45618 | BF3: 45611 | BG3: 45604 | BH3: 45597 | BI3: 45590 | BJ3: 45583 | BK3: 45576 | BL3: 45565 | BM3: 45562 | BN3: 45555 | BO3: 45548 | BP3: 45541 | BQ3: 45534 | BR3: 45527 | BS3: 45520 | BT3: 45513 | BU3: 45506 | BV3: 45499 | BW3: 45492 | BX3: 45485 | BY3: 45478 | BZ3: 45471 | CA3: 45464 | CB3: 45460
B4: 套利 | C4: 鸣石量化24号 | D4: =VLOOKUP(C4,draft!$A:$I,9,FALSE) -> 7.1654 | E4: 5500000 | F4: =D4*$F$1*0.01 -> 6365867.7 | J4: =VLOOKUP(J$3,子基金及业绩基准周净值!$A:$F,2) -> 1.109406 | K4: =VLOOKUP(K$3,子基金及业绩基准周净值!$A:$F,2) -> 1.102846 | L4: =VLOOKUP(L$3,子基金及业绩基准周净值!$A:$F,2) -> 1.11326 | M4: =VLOOKUP(M$3,子基金及业绩基准周净值!$A:$F,2) -> 1.103748 | N4: =VLOOKUP(N$3,子基金及业绩基准周净值!$A:$F,2) -> 1.116786 | O4: =VLOOKUP(O$3,子基金及业绩基准周净值!$A:$F,2) -> 1.099074 | P4: =VLOOKUP(P$3,子基金及业绩基准周净值!$A:$F,2) -> 1.108832 | Q4: =VLOOKUP(Q$3,子基金及业绩基准周净值!$A:$F,2) -> 1.103748 | ... BZ4: =VLOOKUP(BZ$3,子基金及业绩基准周净值!$A:$F,2) -> 1.051
B5: 套利 | C5: 盛冠达量化套利6号 | F5: =D5*$F$1*0.01 -> 0 | J5: - | K5: - | L5: - | M5: - | N5: - | O5: - | P5: - | Q5: - | R5: - | S5: - | T5: - | U5: - | V5: - | W5: - | X5: - | Y5: - | Z5: - | AA5: - | AB5: - | AC5: - | AD5: - | AE5: - | AF5: - | AG5: - | AH5: - | AI5: - | AJ5: - | AK5: - | AL5: - | AM5: - | AN5: - | AO5: - | AP5: - | AQ5: - | AR5: - | AS5: - | AT5: - | AU5: - | AV5: - | AW5: - | AX5: - | AY5: - | AZ5: =VLOOKUP(AZ$3,子基金及业绩基准周净值!$A:$F,3) -> 1.4122 | BA5: =VLOOKUP(BA$3,子基金及业绩基准周净值!$A:$F,3) -> 1.4106 | BB5: =VLOOKUP(BB$3,子基金及业绩基准周净值!$A:$F,3) -> 1.4106 | BC5: =VLOOKUP(BC$3,子基金及业绩基准周净值!$A:$F,3) -> 1.4106 | BD5: =VLOOKUP(BD$3,子基金及业绩基准周净值!$A:$F,3) -> 1.4106 | BE5: =VLOOKUP(BE$3,子基金及业绩基准周净值!$A:$F,3) -> 1.4098 | BF5: =VLOOKUP(BF$3,子基金及业绩基准周净值!$A:$F,3) -> 1.4122 | BG5: =VLOOKUP(BG$3,子基金及业绩基准周净值!$A:$F,3) -> 1.417 | ... BZ5: =VLOOKUP(BZ$3,子基金及业绩基准周净值!$A:$F,3) -> 1.386
B6: 套利 | C6: 因诺期权1号 | D6: =VLOOKUP(C6,draft!$A:$I,9,FALSE) -> 7.0755 | E6: =VLOOKUP(C6,draft!$A:$I,5,FALSE) -> 5000000 | F6: =D6*$F$1*0.01 -> 6285998.9 | J6: =VLOOKUP(J$3,子基金及业绩基准周净值!$A:$F,4) -> 1.7657 | K6: =VLOOKUP(K$3,子基金及业绩基准周净值!$A:$F,4) -> 1.7553 | L6: =VLOOKUP(L$3,子基金及业绩基准周净值!$A:$F,4) -> 1.7406 | M6: =VLOOKUP(M$3,子基金及业绩基准周净值!$A:$F,4) -> 1.747 | N6: =VLOOKUP(N$3,子基金及业绩基准周净值!$A:$F,4) -> 1.7439 | O6: =VLOOKUP(O$3,子基金及业绩基准周净值!$A:$F,4) -> 1.7316 | P6: =VLOOKUP(P$3,子基金及业绩基准周净值!$A:$F,4) -> 1.7257 | Q6: =VLOOKUP(Q$3,子基金及业绩基准周净值!$A:$F,4) -> 1.7169 | ... BY6: =VLOOKUP(BY$3,子基金及业绩基准周净值!$A:$F,4) -> 1.3759
B7: 底仓T | C7: 正瀛骐骥21号 | D7: 0 | F7: =D7*$F$1*0.01 -> 0 | AF7: =VLOOKUP(AF$3,子基金及业绩基准周净值!$A:$F,5) -> 1.0678 | AG7: =VLOOKUP(AG$3,子基金及业绩基准周净值!$A:$F,5) -> 1.068 | AH7: =VLOOKUP(AH$3,子基金及业绩基准周净值!$A:$F,5) -> 1.068 | AI7: =VLOOKUP(AI$3,子基金及业绩基准周净值!$A:$F,5) -> 1.0686 | AJ7: =VLOOKUP(AJ$3,子基金及业绩基准周净值!$A:$F,5) -> 1.0681 | AK7: =VLOOKUP(AK$3,子基金及业绩基准周净值!$A:$F,5) -> 1.0669 | AL7: =VLOOKUP(AL$3,子基金及业绩基准周净值!$A:$F,5) -> 1.0657 | AM7: =VLOOKUP(AM$3,子基金及业绩基准周净值!$A:$F,5) -> 1.0645 | ... BW7: =VLOOKUP(BW$3,子基金及业绩基准周净值!$A:$F,5) -> 1.0227 | BX7: 1.0217
B8: 中性 | C8: 致远量化对冲运作6号 | D8: =VLOOKUP(C8,draft!$A:$I,9,FALSE) -> 7.3547 | E8: =VLOOKUP(C8,draft!$A:$I,5,FALSE) -> 6500000 | F8: =D8*$F$1*0.01 -> 6534045.1 | J8: =VLOOKUP(J$3,子基金及业绩基准周净值!$A:$F,6) -> 1.057 | K8: =VLOOKUP(K$3,子基金及业绩基准周净值!$A:$F,6) -> 1.0638 | L8: =VLOOKUP(L$3,子基金及业绩基准周净值!$A:$F,6) -> 1.0571 | M8: =VLOOKUP(M$3,子基金及业绩基准周净值!$A:$F,6) -> 1.0527 | N8: =VLOOKUP(N$3,子基金及业绩基准周净值!$A:$F,6) -> 1.0496 | O8: =VLOOKUP(O$3,子基金及业绩基准周净值!$A:$F,6) -> 1.0505 | P8: =VLOOKUP(P$3,子基金及业绩基准周净值!$A:$F,6) -> 1.0496 | Q8: =VLOOKUP(Q$3,子基金及业绩基准周净值!$A:$F,6) -> 1.0513 | ... BK8: =VLOOKUP(BK$3,子基金及业绩基准周净值!$A:$F,6) -> 1.0314
B9: 中性 | C9: 磐松市场中性2号 | D9: =VLOOKUP(C9,draft!$A:$I,9,FALSE) -> 2.4526 | E9: =VLOOKUP(C9,draft!$A:$I,5,FALSE) -> 2000000 | F9: =D9*$F$1*0.01 -> 2178933.1 | J9: =VLOOKUP(J$3,子基金及业绩基准周净值!$A:$AU,7) -> 1.1578 | K9: =VLOOKUP(K$3,子基金及业绩基准周净值!$A:$AU,7) -> 1.1599 | L9: =VLOOKUP(L$3,子基金及业绩基准周净值!$A:$AU,7) -> 1.1585 | M9: =VLOOKUP(M$3,子基金及业绩基准周净值!$A:$AU,7) -> 1.1681 | N9: =VLOOKUP(N$3,子基金及业绩基准周净值!$A:$AU,7) -> 1.1675 | O9: =VLOOKUP(O$3,子基金及业绩基准周净值!$A:$AU,7) -> 1.1652 | P9: =VLOOKUP(P$3,子基金及业绩基准周净值!$A:$AU,7) -> 1.1578 | Q9: =VLOOKUP(Q$3,子基金及业绩基准周净值!$A:$AU,7) -> 1.154 | ... BI9: =VLOOKUP(BI$3,子基金及业绩基准周净值!$A:$AU,7) -> 1.0458
B10: 中性 | C10: 量游鸿雁8号 | F10: =D10*$F$1*0.01 -> 0 | AQ10: =VLOOKUP(AQ$3,子基金及业绩基准周净值!$A:$AU,8) -> 1.0919 | AR10: =VLOOKUP(AR$3,子基金及业绩基准周净值!$A:$AU,8) -> 1.086 | AS10: =VLOOKUP(AS$3,子基金及业绩基准周净值!$A:$AU,8) -> 1.1001 | AT10: =VLOOKUP(AT$3,子基金及业绩基准周净值!$A:$AU,8) -> 1.1021 | AU10: =VLOOKUP(AU$3,子基金及业绩基准周净值!$A:$AU,8) -> 1.101 | AV10: =VLOOKUP(AV$3,子基金及业绩基准周净值!$A:$AU,8) -> 1.0969 | AW10: =VLOOKUP(AW$3,子基金及业绩基准周净值!$A:$AU,8) -> 1.0969 | AX10: =VLOOKUP(AX$3,子基金及业绩基准周净值!$A:$AU,8) -> 1.0973 | ... BI10: =VLOOKUP(BI$3,子基金及业绩基准周净值!$A:$AU,8) -> 1.0766
B11: 中性 | C11: 子午中性16号 | T11: =VLOOKUP(T$3,子基金及业绩基准周净值!$A:$AU,9) -> 1.1358 | U11: =VLOOKUP(U$3,子基金及业绩基准周净值!$A:$AU,9) -> 1.14572 | V11: =VLOOKUP(V$3,子基金及业绩基准周净值!$A:$AU,9) -> 1.14564 | W11: =VLOOKUP(W$3,子基金及业绩基准周净值!$A:$AU,9) -> 1.14276 | X11: =VLOOKUP(X$3,子基金及业绩基准周净值!$A:$AU,9) -> 1.14652 | Y11: =VLOOKUP(Y$3,子基金及业绩基准周净值!$A:$AU,9) -> 1.14372 | Z11: =VLOOKUP(Z$3,子基金及业绩基准周净值!$A:$AU,9) -> 1.14604 | AA11: =VLOOKUP(AA$3,子基金及业绩基准周净值!$A:$AU,9) -> 1.13892 | ... BI11: =VLOOKUP(BI$3,子基金及业绩基准周净值!$A:$AU,9) -> 1.0902
B12: 中性 | C12: 世纪前沿松柏量化对冲6号 | D12: =VLOOKUP(C12,draft!$A:$I,9,FALSE) -> 5.97 | E12: =VLOOKUP(C12,draft!$A:$I,5,FALSE) -> 5000000 | F12: =D12*$F$1*0.01 -> 5303853.2 | J12: =VLOOKUP(J$3,子基金及业绩基准周净值!$A:$AU,10) -> 1.0716 | K12: =VLOOKUP(K$3,子基金及业绩基准周净值!$A:$AU,10) -> 1.0744 | L12: =VLOOKUP(L$3,子基金及业绩基准周净值!$A:$AU,10) -> 1.0773 | M12: =VLOOKUP(M$3,子基金及业绩基准周净值!$A:$AU,10) -> 1.0795 | N12: =VLOOKUP(N$3,子基金及业绩基准周净值!$A:$AU,10) -> 1.0676 | O12: =VLOOKUP(O$3,子基金及业绩基准周净值!$A:$AU,10) -> 1.066 | P12: =VLOOKUP(P$3,子基金及业绩基准周净值!$A:$AU,10) -> 1.06 | Q12: =VLOOKUP(Q$3,子基金及业绩基准周净值!$A:$AU,10) -> 1.0581 | ... BI12: =VLOOKUP(BI$3,子基金及业绩基准周净值!$A:$AU,10) -> 0.9951
B13: 打板 | C13: 瀛岳核心 | D13: =VLOOKUP(C13,draft!$A:$I,9,FALSE) -> 3.6254 | E13: =VLOOKUP(C13,draft!$A:$I,5,FALSE) -> 3000000 | F13: =D13*$F$1*0.01 -> 3220869.3 | J13: =VLOOKUP(J$3,子基金及业绩基准周净值!$A:$AU,11) -> 1.7592 | K13: =VLOOKUP(K$3,子基金及业绩基准周净值!$A:$AU,11) -> 1.7521 | L13: =VLOOKUP(L$3,子基金及业绩基准周净值!$A:$AU,11) -> 1.7626 | M13: =VLOOKUP(M$3,子基金及业绩基准周净值!$A:$AU,11) -> 1.7548 | N13: =VLOOKUP(N$3,子基金及业绩基准周净值!$A:$AU,11) -> 1.7382 | O13: =VLOOKUP(O$3,子基金及业绩基准周净值!$A:$AU,11) -> 1.7443 | P13: =VLOOKUP(P$3,子基金及业绩基准周净值!$A:$AU,11) -> 1.7386 | Q13: =VLOOKUP(Q$3,子基金及业绩基准周净值!$A:$AU,11) -> 1.6874 | ... BB13: =VLOOKUP(BB$3,子基金及业绩基准周净值!$A:$AU,11) -> 1.6066 | BC13: 1.6199
B14: 打板 | C14: 创世纪顾锝群英8号 | F14: =D14*$F$1*0.01 -> 0 | W14: =VLOOKUP(W$3,子基金及业绩基准周净值!$A:$AU,12) -> 1.072765 | X14: =VLOOKUP(X$3,子基金及业绩基准周净值!$A:$AU,12) -> 1.072765 | Y14: =VLOOKUP(Y$3,子基金及业绩基准周净值!$A:$AU,12) -> 1.0728346 | Z14: =VLOOKUP(Z$3,子基金及业绩基准周净值!$A:$AU,12) -> 1.0722562 | AA14: =VLOOKUP(AA$3,子基金及业绩基准周净值!$A:$AU,12) -> 1.0728279 | AB14: =VLOOKUP(AB$3,子基金及业绩基准周净值!$A:$AU,12) -> 1.0694995 | AC14: =VLOOKUP(AC$3,子基金及业绩基准周净值!$A:$AU,12) -> 1.0695712 | AD14: =VLOOKUP(AD$3,子基金及业绩基准周净值!$A:$AU,12) -> 1.0727929 | ... AY14: =VLOOKUP(AY$3,子基金及业绩基准周净值!$A:$AU,12) -> 1.0052
B15: 可转债 | C15: 艮岳康柏1号 | D15: =VLOOKUP(C15,draft!$A:$I,9,FALSE) -> 2.5503 | E15: =VLOOKUP(C15,draft!$A:$I,5,FALSE) -> 2000000 | F15: =D15*$F$1*0.01 -> 2265731.5 | J15: =VLOOKUP(J$3,子基金及业绩基准周净值!$A:$AU,13) -> 1.0547 | K15: =VLOOKUP(K$3,子基金及业绩基准周净值!$A:$AU,13) -> 1.0512 | L15: =VLOOKUP(L$3,子基金及业绩基准周净值!$A:$AU,13) -> 1.0361 | M15: =VLOOKUP(M$3,子基金及业绩基准周净值!$A:$AU,13) -> 1.0702 | N15: =VLOOKUP(N$3,子基金及业绩基准周净值!$A:$AU,13) -> 1.0538 | O15: =VLOOKUP(O$3,子基金及业绩基准周净值!$A:$AU,13) -> 1.0501 | P15: =VLOOKUP(P$3,子基金及业绩基准周净值!$A:$AU,13) -> 1.0608 | Q15: =VLOOKUP(Q$3,子基金及业绩基准周净值!$A:$AU,13) -> 1.0571 | ... AW15: =VLOOKUP(AW$3,子基金及业绩基准周净值!$A:$AU,13) -> 0.9164 | AX15: 0.9031
B16: 套利 | C16: 哲萌龙泉进取2号 | D16: =VLOOKUP(C16,draft!$A:$I,9,FALSE) -> 5.9891 | E16: =VLOOKUP(C16,draft!$A:$I,5,FALSE) -> 5100000 | F16: =D16*$F$1*0.01 -> 5320822 | J16: =VLOOKUP(J$3,子基金及业绩基准周净值!$A:$AU,14) -> 1.1243 | K16: =VLOOKUP(K$3,子基金及业绩基准周净值!$A:$AU,14) -> 1.1264 | L16: =VLOOKUP(L$3,子基金及业绩基准周净值!$A:$AU,14) -> 1.1219 | M16: =VLOOKUP(M$3,子基金及业绩基准周净值!$A:$AU,14) -> 1.1286 | N16: =VLOOKUP(N$3,子基金及业绩基准周净值!$A:$AU,14) -> 1.1129 | O16: =VLOOKUP(O$3,子基金及业绩基准周净值!$A:$AU,14) -> 1.1115 | P16: =VLOOKUP(P$3,子基金及业绩基准周净值!$A:$AU,14) -> 1.1189 | Q16: =VLOOKUP(Q$3,子基金及业绩基准周净值!$A:$AU,14) -> 1.1137 | ... AV16: =VLOOKUP(AV$3,子基金及业绩基准周净值!$A:$AU,14) -> 1.0621 | AW16: 1.0582
B17: 套利 | C17: 德贝尊享CTA8号 | F17: =D17*$F$1*0.01 -> 0 | AJ17: =VLOOKUP(AJ$3,子基金及业绩基准周净值!$A:$AU,15) -> 1.041 | AK17: =VLOOKUP(AK$3,子基金及业绩基准周净值!$A:$AU,15) -> 1.046 | AL17: =VLOOKUP(AL$3,子基金及业绩基准周净值!$A:$AU,15) -> 1.043 | AM17: =VLOOKUP(AM$3,子基金及业绩基准周净值!$A:$AU,15) -> 1.053 | AN17: =VLOOKUP(AN$3,子基金及业绩基准周净值!$A:$AU,15) -> 1.06 | AO17: =VLOOKUP(AO$3,子基金及业绩基准周净值!$A:$AU,15) -> 1.06 | AP17: =VLOOKUP(AP$3,子基金及业绩基准周净值!$A:$AU,15) -> 1.058 | AQ17: =VLOOKUP(AQ$3,子基金及业绩基准周净值!$A:$AU,15) -> 1.063 | ... AV17: =VLOOKUP(AV$3,子基金及业绩基准周净值!$A:$AU,15) -> 1.061 | AW17: 1.064
B18: 打板 | C18: 锡和骐骥1号 | D18: =VLOOKUP(C18,draft!$A:$I,9,FALSE) -> 8.7589 | E18: =VLOOKUP(C18,draft!$A:$I,5,FALSE) -> 7100000 | F18: =D18*$F$1*0.01 -> 7781561.2 | J18: =VLOOKUP(J$3,子基金及业绩基准周净值!$A:$AU,16) -> 1.1573 | K18: =VLOOKUP(K$3,子基金及业绩基准周净值!$A:$AU,16) -> 1.1555 | L18: =VLOOKUP(L$3,子基金及业绩基准周净值!$A:$AU,16) -> 1.1553 | M18: =VLOOKUP(M$3,子基金及业绩基准周净值!$A:$AU,16) -> 1.1547 | N18: =VLOOKUP(N$3,子基金及业绩基准周净值!$A:$AU,16) -> 1.1541 | O18: =VLOOKUP(O$3,子基金及业绩基准周净值!$A:$AU,16) -> 1.1536 | P18: =VLOOKUP(P$3,子基金及业绩基准周净值!$A:$AU,16) -> 1.1536 | Q18: =VLOOKUP(Q$3,子基金及业绩基准周净值!$A:$AU,16) -> 1.1511 | ... AV18: =VLOOKUP(AV$3,子基金及业绩基准周净值!$A:$AU,16) -> 1.0234 | AW18: 1.024
B19: 打板 | C19: 特夫郁金香弦理1号 | D19: =VLOOKUP(C19,draft!$A:$I,9,FALSE) -> 3.5055 | E19: =VLOOKUP(C19,draft!$A:$I,5,FALSE) -> 3417520.7 | F19: =D19*$F$1*0.01 -> 3114348 | J19: =VLOOKUP(J$3,子基金及业绩基准周净值!$A:$AU,17) -> 0.995 | K19: =VLOOKUP(K$3,子基金及业绩基准周净值!$A:$AU,17) -> 0.989 | L19: =VLOOKUP(L$3,子基金及业绩基准周净值!$A:$AU,17) -> 0.989 | M19: =VLOOKUP(M$3,子基金及业绩基准周净值!$A:$AU,17) -> 1.1718 | N19: =VLOOKUP(N$3,子基金及业绩基准周净值!$A:$AU,17) -> 1.1732 | O19: =VLOOKUP(O$3,子基金及业绩基准周净值!$A:$AU,17) -> 1.1781 | P19: =VLOOKUP(P$3,子基金及业绩基准周净值!$A:$AU,17) -> 1.1837 | Q19: =VLOOKUP(Q$3,子基金及业绩基准周净值!$A:$AU,17) -> 1.1599 | ... AO19: =VLOOKUP(AO$3,子基金及业绩基准周净值!$A:$AU,17) -> 1.097 | AP19: 1.106
B20: 套利 | C20: 交叉智能-量化套利2号 | D20: =VLOOKUP(C20,draft!$A:$I,9,FALSE) -> 3.4615 | E20: =VLOOKUP(C20,draft!$A:$I,5,FALSE) -> 3000000 | F20: =D20*$F$1*0.01 -> 3075257.6 | J20: =VLOOKUP(J$3,子基金及业绩基准周净值!$A:$AU,18) -> 1.0292 | K20: =VLOOKUP(K$3,子基金及业绩基准周净值!$A:$AU,18) -> 1.0321 | L20: =VLOOKUP(L$3,子基金及业绩基准周净值!$A:$AU,18) -> 1.0294 | M20: =VLOOKUP(M$3,子基金及业绩基准周净值!$A:$AU,18) -> 1.0286 | N20: =VLOOKUP(N$3,子基金及业绩基准周净值!$A:$AU,18) -> 1.0303 | O20: =VLOOKUP(O$3,子基金及业绩基准周净值!$A:$AU,18) -> 1.0224 | P20: =VLOOKUP(P$3,子基金及业绩基准周净值!$A:$AU,18) -> 1.02 | Q20: =VLOOKUP(Q$3,子基金及业绩基准周净值!$A:$AU,18) -> 1.02 | ... AM20: =VLOOKUP(AM$3,子基金及业绩基准周净值!$A:$AU,18) -> 1.0051 | AN20: 1.004
B21: 套利 | C21: 交叉智能启航1号 | F21: =D21*$F$1*0.01 -> 0 | J21: 0.978 | K21: =VLOOKUP(K$3,子基金及业绩基准周净值!$A:$AU,19) -> 0.9815 | L21: =VLOOKUP(L$3,子基金及业绩基准周净值!$A:$AU,19) -> 0.9874 | M21: =VLOOKUP(M$3,子基金及业绩基准周净值!$A:$AU,19) -> 0.9858 | N21: =VLOOKUP(N$3,子基金及业绩基准周净值!$A:$AU,19) -> 0.9929 | O21: =VLOOKUP(O$3,子基金及业绩基准周净值!$A:$AU,19) -> 0.9995 | P21: =VLOOKUP(P$3,子基金及业绩基准周净值!$A:$AU,19) -> 0.9978 | Q21: =VLOOKUP(Q$3,子基金及业绩基准周净值!$A:$AU,19) -> 0.9969 | R21: =VLOOKUP(R$3,子基金及业绩基准周净值!$A:$AU,19) -> 0.993 | ... AM21: =VLOOKUP(AM$3,子基金及业绩基准周净值!$A:$AU,19) -> 0.9999 | AN21: 0.9999
B22: 套利 | C22: 鸣石CTA套利1号 | F22: =D22*$F$1*0.01 -> 0 | Y22: =VLOOKUP(Y$3,子基金及业绩基准周净值!$A:$AU,20) -> 1.0549 | Z22: =VLOOKUP(Z$3,子基金及业绩基准周净值!$A:$AU,20) -> 1.0639 | AA22: =VLOOKUP(AA$3,子基金及业绩基准周净值!$A:$AU,20) -> 1.069 | AB22: =VLOOKUP(AB$3,子基金及业绩基准周净值!$A:$AU,20) -> 1.0718 | AC22: =VLOOKUP(AC$3,子基金及业绩基准周净值!$A:$AU,20) -> 1.0716 | AD22: =VLOOKUP(AD$3,子基金及业绩基准周净值!$A:$AU,20) -> 1.0777 | AE22: =VLOOKUP(AE$3,子基金及业绩基准周净值!$A:$AU,20) -> 1.0811 | AF22: =VLOOKUP(AF$3,子基金及业绩基准周净值!$A:$AU,20) -> 1.0917 | ... AK22: =VLOOKUP(AK$3,子基金及业绩基准周净值!$A:$AU,20) -> 1.0911 | AL22: 1.0776
B23: 打板 | C23: 创世纪顾锝屠龙1号 | D23: =VLOOKUP(C23,draft!$A:$I,9,FALSE) -> 3.5485 | E23: =VLOOKUP(C23,draft!$A:$I,5,FALSE) -> 3000000 | F23: =D23*$F$1*0.01 -> 3152550 | J23: =VLOOKUP(J$3,子基金及业绩基准周净值!$A:$AU,21) -> 1.1037 | K23: =VLOOKUP(K$3,子基金及业绩基准周净值!$A:$AU,21) -> 1.10214 | L23: =VLOOKUP(L$3,子基金及业绩基准周净值!$A:$AU,21) -> 1.10246 | M23: =VLOOKUP(M$3,子基金及业绩基准周净值!$A:$AU,21) -> 1.10254 | N23: =VLOOKUP(N$3,子基金及业绩基准周净值!$A:$AU,21) -> 1.10054 | O23: =VLOOKUP(O$3,子基金及业绩基准周净值!$A:$AU,21) -> 1.0973 | P23: =VLOOKUP(P$3,子基金及业绩基准周净值!$A:$AU,21) -> 1.0953 | Q23: =VLOOKUP(Q$3,子基金及业绩基准周净值!$A:$AU,21) -> 1.08862 | ... AD23: =VLOOKUP(AD$3,子基金及业绩基准周净值!$A:$AU,21) -> 1.0503
B24: 宏观 | C24: 远澜藤枫6号 | D24: =VLOOKUP(C24,draft!$A:$I,9,FALSE) -> 2.433 | E24: =VLOOKUP(C24,draft!$A:$I,5,FALSE) -> 2000000 | F24: =D24*$F$1*0.01 -> 2161520.1 | J24: =VLOOKUP(J$3,子基金及业绩基准周净值!$A:$AU,22) -> 1.0784 | K24: =VLOOKUP(K$3,子基金及业绩基准周净值!$A:$AU,22) -> 1.0776 | L24: =VLOOKUP(L$3,子基金及业绩基准周净值!$A:$AU,22) -> 1.0864 | M24: =VLOOKUP(M$3,子基金及业绩基准周净值!$A:$AU,22) -> 1.0727 | N24: =VLOOKUP(N$3,子基金及业绩基准周净值!$A:$AU,22) -> 1.052 | O24: =VLOOKUP(O$3,子基金及业绩基准周净值!$A:$AU,22) -> 1.0435 | P24: =VLOOKUP(P$3,子基金及业绩基准周净值!$A:$AU,22) -> 1.0488 | Q24: =VLOOKUP(Q$3,子基金及业绩基准周净值!$A:$AU,22) -> 1.041 | ... AD24: =VLOOKUP(AD$3,子基金及业绩基准周净值!$A:$AU,22) -> 0.9978
B25: 多空 | C25: 悦海盈和18号 | D25: =VLOOKUP(C25,draft!$A:$I,9,FALSE) -> 3.4309 | E25: =VLOOKUP(C25,draft!$A:$I,5,FALSE) -> 3000000 | F25: =D25*$F$1*0.01 -> 3048072 | J25: =VLOOKUP(J$3,子基金及业绩基准周净值!$A:$AU,23) -> 1.33424 | K25: =VLOOKUP(K$3,子基金及业绩基准周净值!$A:$AU,23) -> 1.3416 | L25: =VLOOKUP(L$3,子基金及业绩基准周净值!$A:$AU,23) -> 1.3316 | M25: =VLOOKUP(M$3,子基金及业绩基准周净值!$A:$AU,23) -> 1.33176 | N25: =VLOOKUP(N$3,子基金及业绩基准周净值!$A:$AU,23) -> 1.3268 | O25: =VLOOKUP(O$3,子基金及业绩基准周净值!$A:$AU,23) -> 1.32888 | P25: =VLOOKUP(P$3,子基金及业绩基准周净值!$A:$AU,23) -> 1.32744 | Q25: =VLOOKUP(Q$3,子基金及业绩基准周净值!$A:$AU,23) -> 1.3236 | ... Y25: =VLOOKUP(Y$3,子基金及业绩基准周净值!$A:$AU,23) -> 1.3099 | Z25: 1.3132
B26: 多空 | C26: 玄元元中10号 | D26: =VLOOKUP(C26,draft!$A:$I,9,FALSE) -> 1.683 | E26: =VLOOKUP(C26,draft!$A:$I,5,FALSE) -> 1500000 | F26: =D26*$F$1*0.01 -> 1495206.9 | J26: =VLOOKUP(J$3,子基金及业绩基准周净值!$A:$AU,24) -> 1.0014 | K26: =VLOOKUP(K$3,子基金及业绩基准周净值!$A:$AU,24) -> 1.0083 | L26: =VLOOKUP(L$3,子基金及业绩基准周净值!$A:$AU,24) -> 1.0018 | M26: =VLOOKUP(M$3,子基金及业绩基准周净值!$A:$AU,24) -> 0.9998 | N26: =VLOOKUP(N$3,子基金及业绩基准周净值!$A:$AU,24) -> 1.0022 | O26: =VLOOKUP(O$3,子基金及业绩基准周净值!$A:$AU,24) -> 1.0011 | P26: =VLOOKUP(P$3,子基金及业绩基准周净值!$A:$AU,24) -> 1.0019 | Q26: =VLOOKUP(Q$3,子基金及业绩基准周净值!$A:$AU,24) -> 1.0041 | ... Y26: =VLOOKUP(Y$3,子基金及业绩基准周净值!$A:$AU,24) -> 1.0046
B27: 多空 | C27: 玄元元中12号 | D27: =VLOOKUP(C27,draft!$A:$I,9,FALSE) -> 1.684 | E27: =VLOOKUP(C27,draft!$A:$I,5,FALSE) -> 1500000 | F27: =D27*$F$1*0.01 -> 1496095.3 | J27: =VLOOKUP(J$3,子基金及业绩基准周净值!$A:$AU,25) -> 0.996 | K27: =VLOOKUP(K$3,子基金及业绩基准周净值!$A:$AU,25) -> 1.002 | L27: =VLOOKUP(L$3,子基金及业绩基准周净值!$A:$AU,25) -> 0.996 | M27: =VLOOKUP(M$3,子基金及业绩基准周净值!$A:$AU,25) -> 0.9977 | N27: =VLOOKUP(N$3,子基金及业绩基准周净值!$A:$AU,25) -> 0.9965 | O27: =VLOOKUP(O$3,子基金及业绩基准周净值!$A:$AU,25) -> 0.9959 | P27: =VLOOKUP(P$3,子基金及业绩基准周净值!$A:$AU,25) -> 0.9983 | Q27: =VLOOKUP(Q$3,子基金及业绩基准周净值!$A:$AU,25) -> 0.9989 | ... Y27: =VLOOKUP(Y$3,子基金及业绩基准周净值!$A:$AU,25) -> 0.9986
B28: 多空 | C28: 磐松多空对冲5号 | D28: =VLOOKUP(C28,draft!$A:$I,9,FALSE) -> 5.5788 | E28: =VLOOKUP(C28,draft!$A:$I,5,FALSE) -> 5000000 | F28: =D28*$F$1*0.01 -> 4956304.3 | J28: =VLOOKUP(J$3,子基金及业绩基准周净值!$A:$AU,26) -> 1.2472 | K28: =VLOOKUP(K$3,子基金及业绩基准周净值!$A:$AU,26) -> 1.2521 | L28: =VLOOKUP(L$3,子基金及业绩基准周净值!$A:$AU,26) -> 1.2467 | M28: =VLOOKUP(M$3,子基金及业绩基准周净值!$A:$AU,26) -> 1.2543 | N28: =VLOOKUP(N$3,子基金及业绩基准周净值!$A:$AU,26) -> 1.2584 | O28: =VLOOKUP(O$3,子基金及业绩基准周净值!$A:$AU,26) -> 1.2524 | P28: =VLOOKUP(P$3,子基金及业绩基准周净值!$A:$AU,26) -> 1.244 | Q28: =VLOOKUP(Q$3,子基金及业绩基准周净值!$A:$AU,26) -> 1.243 | ... Y28: =VLOOKUP(Y$3,子基金及业绩基准周净值!$A:$AU,26) -> 1.2582
B29: 中性 | C29: 量子智盈6号 | F29: =D29*$F$1*0.01 -> 0 | N29: =VLOOKUP(N$3,子基金及业绩基准周净值!$A:$AU,27) -> 0.9788 | O29: =VLOOKUP(O$3,子基金及业绩基准周净值!$A:$AU,27) -> 0.9695 | P29: =VLOOKUP(P$3,子基金及业绩基准周净值!$A:$AU,27) -> 0.9859 | Q29: =VLOOKUP(Q$3,子基金及业绩基准周净值!$A:$AU,27) -> 0.9948 | R29: =VLOOKUP(R$3,子基金及业绩基准周净值!$A:$AU,27) -> 1.0005 | S29: =VLOOKUP(S$3,子基金及业绩基准周净值!$A:$AU,27) -> 1.0437 | T29: =VLOOKUP(T$3,子基金及业绩基准周净值!$A:$AU,27) -> 1.0506 | U29: =VLOOKUP(U$3,子基金及业绩基准周净值!$A:$AU,27) -> 1.092 | ... Y29: =VLOOKUP(Y$3,子基金及业绩基准周净值!$A:$AU,27) -> 1.0666
B30: 中性 | C30: 垒昂金鹿13号 | D30: =VLOOKUP(C30,draft!$A:$I,9,FALSE) -> 4.8569 | E30: =VLOOKUP(C30,draft!$A:$I,5,FALSE) -> 4500000 | F30: =D30*$F$1*0.01 -> 4314955.6 | J30: =VLOOKUP(J$3,子基金及业绩基准周净值!$A:$AU,28) -> 0.9566 | K30: =VLOOKUP(K$3,子基金及业绩基准周净值!$A:$AU,28) -> 0.9605 | L30: =VLOOKUP(L$3,子基金及业绩基准周净值!$A:$AU,28) -> 0.9563 | M30: =VLOOKUP(M$3,子基金及业绩基准周净值!$A:$AU,28) -> 0.9581 | N30: =VLOOKUP(N$3,子基金及业绩基准周净值!$A:$AU,28) -> 0.9577 | O30: =VLOOKUP(O$3,子基金及业绩基准周净值!$A:$AU,28) -> 0.9608 | P30: =VLOOKUP(P$3,子基金及业绩基准周净值!$A:$AU,28) -> 0.9669 | Q30: =VLOOKUP(Q$3,子基金及业绩基准周净值!$A:$AU,28) -> 0.9652 | ... Y30: =VLOOKUP(Y$3,子基金及业绩基准周净值!$A:$AU,28) -> 0.9927
B31: 择时多头 | C31: 悦海盈和12号 | D31: =VLOOKUP(C31,draft!$A:$I,9,FALSE) -> 5.3681 | E31: =VLOOKUP(C31,draft!$A:$I,5,FALSE) -> 4800000 | F31: =D31*$F$1*0.01 -> 4769114.7 | J31: =VLOOKUP(J$3,子基金及业绩基准周净值!$A:$AU,29) -> 1.7275 | K31: =VLOOKUP(K$3,子基金及业绩基准周净值!$A:$AU,29) -> 1.7406 | L31: =VLOOKUP(L$3,子基金及业绩基准周净值!$A:$AU,29) -> 1.7481 | M31: =VLOOKUP(M$3,子基金及业绩基准周净值!$A:$AU,29) -> 1.7279 | N31: =VLOOKUP(N$3,子基金及业绩基准周净值!$A:$AU,29) -> 1.6931 | O31: =VLOOKUP(O$3,子基金及业绩基准周净值!$A:$AU,29) -> 1.7227 | P31: =VLOOKUP(P$3,子基金及业绩基准周净值!$A:$AU,29) -> 1.7619 | Q31: =VLOOKUP(Q$3,子基金及业绩基准周净值!$A:$AU,29) -> 1.7501 | R31: =VLOOKUP(R$3,子基金及业绩基准周净值!$A:$AU,29) -> 1.7411 | S31: 1.7387
B32: 指增保护 | C32: 因诺天跃19号 | D32: =VLOOKUP(C32,draft!$A:$I,9,FALSE) -> 3.3999 | E32: =VLOOKUP(C32,draft!$A:$I,5,FALSE) -> 3000000 | F32: =D32*$F$1*0.01 -> 3020531.1 | J32: =VLOOKUP(J$3,子基金及业绩基准周净值!$A:$AU,30) -> 1.2997 | K32: =VLOOKUP(K$3,子基金及业绩基准周净值!$A:$AU,30) -> 1.2948 | L32: =VLOOKUP(L$3,子基金及业绩基准周净值!$A:$AU,30) -> 1.2697 | M32: 1.2921
B33: 指增保护 | C33: 念觉500指增稳健Plus27号 | D33: =VLOOKUP(C33,draft!$A:$I,9,FALSE) -> 3.3852 | E33: =VLOOKUP(C33,draft!$A:$I,5,FALSE) -> 3000000 | F33: =D33*$F$1*0.01 -> 3007471.4 | J33: =VLOOKUP(J$3,子基金及业绩基准周净值!$A:$AU,31) -> 0.9625 | K33: =VLOOKUP(K$3,子基金及业绩基准周净值!$A:$AU,31) -> 0.959 | L33: 0.9601
B34: 指增保护 | C34: 天算指增保护6号 | D34: =VLOOKUP(C34,draft!$A:$I,9,FALSE) -> 3.3811 | E34: =VLOOKUP(C34,draft!$A:$I,5,FALSE) -> 3000000 | F34: =D34*$F$1*0.01 -> 3003828.8 | J34: =VLOOKUP(J$3,子基金及业绩基准周净值!$A:$AU,32) -> 1.2488 | K34: =VLOOKUP(K$3,子基金及业绩基准周净值!$A:$AU,32) -> 1.2513 | L34: 1.2472
B35: 子基金收益率 | CB35: 成立日期
B36: 策略 | C36: 子基金 | D36: 市值占净值 | E36: 成本 | F36: 市值 | G36: 持仓收益 | H36: 持仓收益率 | I36: 下投期间涨跌幅 | J36: 45961 | K36: 45954 | L36: 45947 | M36: 45940 | N36: 45926 | O36: 45919 | P36: 45912 | Q36: 45905 | R36: 45898 | S36: 45891 | T36: 45884 | U36: 45877 | V36: 45870 | W36: 45863 | X36: 45856 | Y36: 45849 | Z36: 45842 | AA36: 45835 | AB36: 45828 | AC36: 45821 | AD36: 45814 | AE36: 45807 | AF36: 45800 | AG36: 45793 | AH36: 45786 | AI36: 45772 | AJ36: 45765 | AK36: 45758 | AL36: 45750 | AM36: 45744 | AN36: 45737 | AO36: 45730 | AP36: 45723 | AQ36: 45716 | AR36: 45709 | AS36: 45702 | AT36: 45695 | AU36: 45684 | AV36: 45681 | AW36: 45674 | AX36: 45667 | AY36: 45660 | AZ36: 45653 | BA36: 45646 | BB36: 45639 | BC36: 45632 | BD36: 45625 | BE36: 45618 | BF36: 45611 | BG36: 45604 | BH36: 45597 | BI36: 45590 | BJ36: 45583 | BK36: 45576 | BL36: =BL3 -> 45565 | BM36: =BM3 -> 45562 | BN36: =BN3 -> 45555 | BO36: =BO3 -> 45548 | BP36: =BP3 -> 45541 | BQ36: =BQ3 -> 45534 | BR36: =BR3 -> 45527 | BS36: =BS3 -> 45520 | ... CB36: =CB3 -> 45460
B37: 套利 | C37: 鸣石量化24号 | D37: =D4 -> 7.1654 | E37: =E4 -> 5500000 | F37: =D37*$F$1*0.01 -> 6365867.7 | G37: =F37-E37 -> 865867.68 | H37: =G37/E37 -> 0.15743049 | I37: =(J4/1.0588)*(1.1474/1.051)-1 -> 0.1439017 | J37: =J4/K4-1 -> 0.0059482466 | K37: =K4/L4-1 -> -0.0093545084 | L37: =L4/M4-1 -> 0.0086179092 | M37: =M4/N4-1 -> -0.011674573 | N37: =N4/O4-1 -> 0.016115384 | O37: =O4/P4-1 -> -0.0088002511 | P37: =P4/Q4-1 -> 0.0046061239 | Q37: =Q4/R4-1 -> -0.0014836419 | ... AX37: =AX4/AY4-1 -> 0.0060813379 | AY37: 0.0092 | AZ37: =AZ4/BA4-1 -> -0.0026966827 | BA37: =BA4/BB4-1 -> 0.00043749122 | BB37: =BB4/BC4-1 -> 0.011207323 | BC37: =BC4/BD4-1 -> -0.0046236628 | BD37: =BD4/BE4-1 -> -0.0016120097 | BE37: =BE4/BF4-1 -> 0.0015411078 | BF37: =BF4/BG4-1 -> 0.0090339849 | BG37: =BG4/BH4-1 -> 0.024115461 | ... BY37: =BY4/BZ4-1 -> 0.00076117983
B38: 套利 | C38: 盛冠达量化套利6号 | E38: 0 | F38: =D38*$F$1*0.01 -> 0 | G38: =F38-E38 -> 0 | I38: =AZ5/BZ5-1 -> 0.018903319 | AJ38: - | AK38: - | AL38: - | AM38: - | AN38: - | AO38: - | AP38: - | AQ38: - | AR38: - | AS38: - | AT38: - | AU38: - | AV38: - | AW38: - | AX38: - | AY38: - | AZ38: =AZ5/BA5-1 -> 0.0011342691 | BA38: =BA5/BB5-1 -> 0 | BB38: =BB5/BC5-1 -> 0 | BC38: =BC5/BD5-1 -> 0 | BD38: =BD5/BE5-1 -> 0.00056745638 | BE38: =BE5/BF5-1 -> -0.001699476 | BF38: =BF5/BG5-1 -> -0.0033874382 | BG38: =BG5/BH5-1 -> -0.0028149191 | ... BY38: =BY5/BZ5-1 -> 0.00072150072
B39: 套利 | C39: 因诺期权1号 | D39: =D6 -> 7.0755 | E39: =E6 -> 5000000 | F39: =D39*$F$1*0.01 -> 6285998.9 | G39: =F39-E39 -> 1285998.9 | H39: =G39/E39 -> 0.25719979 | I39: =J6/BY6-1 -> 0.28330547 | J39: =J6/K6-1 -> 0.0059249131 | K39: =K6/L6-1 -> 0.0084453637 | L39: =L6/M6-1 -> -0.003663423 | M39: =M6/N6-1 -> 0.0017776249 | N39: =N6/O6-1 -> 0.0071032571 | O39: =O6/P6-1 -> 0.0034189025 | P39: =P6/Q6-1 -> 0.0051255169 | Q39: =Q6/R6-1 -> 0.0065662191 | ... BX39: =BX6/BY6-1 -> 0.0019623519
B40: 底仓T | C40: 正瀛骐骥21号 | D40: =D7 -> 0 | I40: =AF7/BX7-1 -> 0.045120877 | AF40: =AF7/AG7-1 -> -0.00018726592 | AG40: =AG7/AH7-1 -> 0 | AH40: =AH7/AI7-1 -> -0.00056148231 | AI40: =AI7/AJ7-1 -> 0.00046812096 | AJ40: =AJ7/AK7-1 -> 0.001124754 | AK40: =AK7/AL7-1 -> 0.0011260205 | AL40: =AL7/AM7-1 -> 0.0011272898 | AM40: =AM7/AN7-1 -> 0.0010344179 | ... BW40: =BW7/BX7-1 -> 0.00097876089
...

Sheet draft
A1: =周报!A3 -> 45961
B2: 科目名称 | C2: 数量 | D2: 单位成本 | E2: 成本 | F2: 成本占净值% | G2: 市价 | H2: 市值 | I2: 市值占净值%
A3: 致远量化对冲运作6号 | B3: 致远量化对冲运作6号私募证券投资基金B类 | C3: 6181714.4 | D3: 1.0515 | E3: 6500000 | F3: 7.3164 | G3: 1.057 | H3: 6534072.1 | I3: 7.3547 | J3: 34072.11 | K3: 【正常交易_手工行情】
A4: 交叉智能-量化套利2号 | B4: 交叉智能-量化套利2号私募证券投资基金 | C4: 2988047.8 | D4: 1.004 | E4: 3000000 | F4: 3.3768 | G4: 1.0292 | H4: 3075298.8 | I4: 3.4615 | J4: 75298.81 | K4: 【正常交易_手工行情】
A5: 哲萌龙泉进取2号 | B5: 哲萌龙泉进取2号私募证券投资基金A类 | C5: 4732536 | D5: 1.0776 | E5: 5100000 | F5: 5.7405 | G5: 1.1243 | H5: 5320790.3 | I5: 5.9891 | J5: 220790.28 | K5: 【正常交易_手工行情】
A6: 世纪前沿松柏量化对冲6号 | B6: 世纪前沿松柏量化对冲6号私募证券投资基金C类 | C6: 4949500.1 | D6: 1.0102 | E6: 5000000 | F6: 5.628 | G6: 1.0716 | H6: 5303884.3 | I6: 5.97 | J6: 303884.26 | K6: 【正常交易_手工行情】
A7: 创世纪顾锝屠龙1号 | B7: 创世纪顾锝屠龙1号私募证券投资基金B类 | C7: 2856326.8 | D7: 1.0503 | E7: 3000000 | F7: 3.3768 | G7: 1.1037 | H7: 3152527.9 | I7: 3.5485 | J7: 152527.85 | K7: 【正常交易_手工行情】
A8: 锡和骐骥1号 | B8: 锡和骐骥1号私募证券投资基金A类 | C8: 6723871.6 | D8: 1.0559 | E8: 7100000 | F8: 7.9917 | G8: 1.1573 | H8: 7781536.7 | I8: 8.7589 | J8: 681536.65 | K8: 【正常交易_手工行情】
A9: 远澜藤枫6号 | B9: 远澜藤枫宏观量化6号私募证券投资基金C类 | C9: 2004409.7 | D9: 0.9978 | E9: 2000000 | F9: 2.2512 | G9: 1.0784 | H9: 2161555.4 | I9: 2.433 | J9: 161555.42 | K9: 【正常交易_手工行情】
A10: 垒昂金鹿13号 | B10: 垒昂金鹿量化对冲13号私募证券投资基金B类 | C10: 4510730.5 | D10: 0.9976 | E10: 4500000 | F10: 5.0652 | G10: 0.9566 | H10: 4314964.8 | I10: 4.8569 | J10: -185035.16 | K10: 【正常交易_手工行情】
A11: 玄元元中10号 | B11: 玄元元中10号私募证券投资基金B类 | C11: 1493131.6 | D11: 1.0046 | E11: 1500000 | F11: 1.6884 | G11: 1.0014 | H11: 1495222 | I11: 1.683 | J11: -4778.03 | K11: 【正常交易_手工行情】
A12: 玄元元中12号 | B12: 玄元元中12号私募证券投资基金B类 | C12: 1502102.9 | D12: 0.9986 | E12: 1500000 | F12: 1.6884 | G12: 0.996 | H12: 1496094.5 | I12: 1.684 | J12: -3905.47 | K12: 【正常交易_手工行情】
A13: 念觉500指增稳健Plus27号 | B13: 念觉500指增稳健Plus27号私募证券投资基金B类 | C13: 3124674.5 | D13: 0.9601 | E13: 3000000 | F13: 3.3768 | G13: 0.9625 | H13: 3007499.2 | I13: 3.3852 | J13: 7499.22 | K13: 【正常交易_手工行情】
A14: 天算指增保护6号 | B14: 天算指增保护尊享6号私募证券投资基金C类 | C14: 2405388.1 | D14: 1.2472 | E14: 3000000 | F14: 3.3768 | G14: 1.2488 | H14: 3003848.6 | I14: 3.3811 | J14: 3848.62 | K14: 【正常交易_手工行情】
... A24: 瀛岳核心 | B24: 瀛岳核心私募证券投资基金A类 | C24: 1830877.2 | D24: 1.6386 | E24: 3000000 | F24: 3.3768 | G24: 1.7592 | H24: 3220879.2 | I24: 3.6254 | J24: 220879.24 | K24: 【正常交易_手工行情】

Sheet 监控指标
A1: 宏源期货启后私享1号资管计划投后监控指标
A2: 日期 | B2: =业绩归因!$C$1 -> 45961
A3: 一、业绩监控
A4: 监控目标 | B4: 监控指标 | G4: 预警阈值 | I4: 本周 | K4: 策略 | N4: 业绩基准 | R4: 最大回撤预设标准
A5: FOF | B5: 最大回撤 | G5: ≥5% | I5: =VLOOKUP(B2,启后私享1号FOF周净值!A:M,11) -> 否 | K5: 量化中性策略 | N5: 朝阳永续股票市场中性细分策略指数 | R5: 回撤达到5%
B6: 单位净值 | G6: ≤0.95 | I6: =VLOOKUP(B2,启后私享1号FOF周净值!A:M,12) -> 否 | K6: 套利/期权策略 | N6: 朝阳永续套利策略宽基指数 | R6: 回撤达到5%
B7: 周度收益率跌幅 | G7: ≥2% | I7: =VLOOKUP(B2,启后私享1号FOF周净值!A:M,13) -> 否 | K7: 打板策略 | N7: 打板拟合指数（打板+0.2*炸板）*0.2 | R7: 回撤达到5%
A8: 子基金 | B8: 周收益率跌幅 | G8: ≥3% | I8: 否 | K8: 转债策略 | N8: 万得可转债等权（889033） | R8: 回撤达到5%
B9: 持有期最大回撤（预设基准见右侧） | G9: ≥预设标准 | I9: 否 | K9: 宏观策略 | N9: 宏观拟合指数（南华黄金*0.3+南华商品*0.1+中证全指*0.13+五年国债主连*0.47）
B10: 周度超额收益连续为负（业绩基准见右侧) | G10: ≥4周 | I10: 否 | K10: 择时多头策略 | N10: 灵活对冲指数（1000指增细分*0.8+股票市场中性*0.2）
G12: 业绩异动
G13: 产品及负超额周数
G14: 4
G15: 5 | H15: 磐松多空对冲5号、玄元元中12号
G16: 6 | H16: 特夫郁金香弦理1号
G17: 7 | H17: 锡和骐骥1号、创世纪顾锝屠龙1号、垒昂金鹿13号
G18: 8
A19: 二、子基金异动监控 | C19: 注：若无变动则不特别说明 | G19: 9
A20: 1 | B20: 策略变动
A21: 2 | B21: 管理人高管、股东、核心团队人员变动
A22: 3 | B22: 发生基金分红、拆分
A23: 4 | B23: 行政处罚、法律诉讼
A24: 5 | B24: 基金经理变动
A25: 6 | B25: 触发预警线、止损线
A26: 7 | B26: 基金状态变动、工商登记信息变动
A27: 8 | B27: 其他异动指标
A28: 管理人基金业协会变动 | G28: 管理人其他异动
A29: 序号 | B29: 公司名称 | C29: 是否有变更 | D29: 变更内容 | E29: 变更提交时间 | F29: 是否有新增变更 | G29: 45694 | H29: 【量游鸿雁8号】基金经理曲平离职，因产品募资进度慢，寻求更好平台
A30: 1 | B30: 致诚卓远(珠海)投资管理合伙企业(有限合伙） | C30: 是 | D30: 主体资格证明文件及相关内容变更 | E30: 45285 | F30: 否 | G30: 45700 | H30: 风控测算2025年1月底产品不满足衍生品类，主要是合约价值不足80%，需要增加衍生品类资产投资
A31: 2 | B31: 因诺（上海）资产管理有限公司 | C31: 是 | D31: 主体资格证明文件及相关内容变更, 高管变更 | E31: 45533 | F31: 否 | H31: 风控测算【磐松市场中性2号】2025年1月底持有19%合约价值的股指多头合约
A32: 3 | B32: 上海子午投资管理有限公司 | C32: 无 | F32: 否 | G32: 45728 | H32: 风控测算2025年2月底产品满足衍生品类，主要是【鸣石量化24号】合约价值突增
A33: 4 | B33: 上海磐松私募基金管理有限公司 | C33: 是 | D33: 高管变更 | E33: 45845 | F33: 否 | H33: 投资穿透2月底估值表发现【子午中性16号】股票仓位仅37%，已于当日和子午投资经理许忞进行投后交流
A34: 5 | B34: 上海量游资产管理有限公司 | C34: 无 | F34: 否 | G34: 45764 | H34: 杭州艮岳主体资格证明文件及相关内容变更
A35: 6 | B35: 海南世纪前沿私募基金管理有限公司 | C35: 是 | D35: 高管变更，状态办理通过 | E35: 45896 | F35: 否 | G35: 45772 | H35: 蓝色郁金香主体资格证明文件及相关内容变更,出资人变更
A36: 7 | B36: 上海顾锝私募基金管理有限公司 | C36: 是 | D36: 出资人变更 | E36: 45639 | F36: 否 | G36: 45806 | H36: 锡和高管变更，经与管理人沟通了解，为更好应对监管检查，风控主管变更为许丽华，前风控主管变更为普通风控岗。
A37: 8 | B37: 上海特夫私募基金管理有限公司 | C37: 是 | D37: 主体资格证明文件及相关内容变更,出资人变更 | E37: 45772 | F37: 否 | G37: 45846 | H37: 将张潇由执行董事变为董事长，设立董事会。计划未来通过员工持股平台给投研股份。具体章程磐松内部合规还在拟。
A38: 9 | B38: 共青城瀛岳私募基金管理有限公司 | C38: 无 | F38: 否 | G38: 45890 | H38: 海南世纪前沿私募基金管理有限公司有变更，调整高管职位以及添加新高管，陈家馨职位由副总经理调整为董事长，新添加周志豪为董事总经理，以上变更正在办理中
A39: 10 | B39: 锡和私募基金管理（上海）有限公司 | C39: 是 | D39: 高管变更 | E39: 45799 | F39: 否 | G39: 45896 | H39: 海南世纪前沿私募基金管理有限公司高管变更办理通过。
A40: 11 | B40: 上海德贝私募基金管理有限公司 | C40: 无 | F40: 否
A41: 12 | B41: 杭州艮岳私募基金管理有限公司 | C41: 是 | D41: 主体资格证明文件及相关内容变更 | E41: 45764 | F41: 否
...

Sheet 调仓指令
A1: 日期 | B1: =TODAY() -> 45967
A2: 启后私享1号FOF（每周三开放）
A3: 状态（产品经理填写） | B3: 倒计时 | C3: 日期 | E3: 子基金 | F3: 代码 | G3: 方向 | H3: 金额/份额 | J3: 备注 | K3: 平台
A4: 已操作 | B4: =C4-$B$1 -> -506 | C4: 45461 | D4: =C4 -> 45461 | E4: 国寿安保添利货币B | F4: 003423 | G4: 申购 | H4: 12300000 | I4: 1230w元 | J4: 备案期间买货基 | K4: 招嬴通
A5: 已操作 | B5: =C5-$B$1 -> -498 | C5: 45469 | D5: =C5 -> 45469 | E5: 盛冠达量化套利6号 | G5: 申购 | H5: 3000000 | I5: 300w元 | J5: 周三申购
A6: 已操作 | B6: =C6-$B$1 -> -498 | C6: 45469 | D6: =C6 -> 45469 | E6: 鸣石量化24号 | G6: 申购 | H6: 7500000 | I6: 750w元 | J6: 日开申购
A7: 已操作 | B7: =C7-$B$1 -> -492 | C7: 45475 | D7: =C7 -> 45475 | E7: 因诺期权1号 | G7: 申购 | H7: 2000000 | I7: 200w元 | J7: 周二申购，分两批买
A8: 已操作 | B8: =C8-$B$1 -> -486 | C8: 45481 | D8: =C8 -> 45481 | E8: 国寿安保添利货币B | F8: 003423 | G8: 申购 | H8: 5000000 | I8: 500w元 | J8: 等等基差，先买货基 | K8: 招嬴通
A9: 已操作 | B9: =C9-$B$1 -> -485 | C9: 45482 | D9: =C9 -> 45482 | E9: 因诺期权1号 | G9: 申购 | H9: 3000000 | I9: 300w元 | J9: 周二申购
A10: 已操作 | B10: =C10-$B$1 -> -479 | C10: 45488 | D10: =C10 -> 45488 | E10: 国寿安保添利货币B | F10: 003423 | G10: 赎回 | H10: 2000000 | I10: 200w元 | J10: T+1到账后买正瀛 | K10: 招嬴通
A11: 已操作 | B11: =C11-$B$1 -> -477 | C11: 45490 | D11: =C11 -> 45490 | E11: 正瀛骐骥21号 | G11: 申购 | H11: 2000000 | I11: 200w元 | J11: 每周1、3工作日申购
A12: 已操作 | B12: =C12-$B$1 -> -402 | C12: 45565 | D12: 45565 | E12: 国寿安保添利货币B | F12: 003423 | G12: 赎回 | H12: 3000000 | I12: 全部赎回 | K12: 招嬴通
A13: 已操作 | B13: =C13-$B$1 -> -394 | C13: 45573 | D13: 45573 | E13: 致诚卓远量化对冲运作6号 | G13: 申购 | H13: 3000000 | I13: 300w元 | J13: 日开，之前值信投过，不用审合同了，看法审承诺函还能用吗
A14: 已操作 | B14: =C14-$B$1 -> -380 | C14: 45587 | D14: 45587 | E14: 致诚卓远量化对冲运作6号 | G14: 申购 | H14: 1500000 | I14: 150w元 | J14: 日开，之前值信投过，不用审合同了，看法审承诺函还能用吗
A15: 已操作 | B15: =C15-$B$1 -> -380 | C15: 45587 | D15: 45587 | E15: 磐松市场中性2号 | G15: 申购 | H15: 2000000 | I15: 200w元 | J15: 日开，之前云帆投过，不用审合同了，看法审承诺函还能用吗
A16: 已操作 | B16: =C16-$B$1 -> -380 | C16: 45587 | D16: 45587 | E16: 量游鸿雁8号 | G16: 申购 | H16: 1000000 | I16: 100w元 | J16: 每周2、5
A17: 已操作 | B17: =C17-$B$1 -> -380 | C17: 45587 | D17: 45587 | E17: 子午中性16号 | G17: 申购 | H17: 1000000 | I17: 100w元 | J17: 每周二开放
A18: 已操作 | B18: =C18-$B$1 -> -379 | C18: 45588 | D18: 45588 | E18: 世纪前沿松柏量化对冲6号C | G18: 申购 | H18: 4000000 | I18: 400w元 | J18: 每周三
A19: 已操作 | B19: =C19-$B$1 -> -330 | C19: 45637 | D19: 45588 | E19: 瀛岳核心 | G19: 申购 | H19: 3000000 | I19: 300w元 | J19: 每周三
A20: 已操作 | B20: =C20-$B$1 -> -310 | C20: 45657 | D20: 45589 | E20: 盛冠达量化套利6号 | G20: 赎回 | I20: 全部赎回 | J20: 每月末开放赎回
A21: 已操作 | B21: =C21-$B$1 -> -303 | C21: 45664 | D21: 星期二 | E21: 顾锝群英8号 | G21: 申购 | H21: 3000000 | I21: 300w元 | J21: 每周二、三
A22: 已操作 | B22: =C22-$B$1 -> -303 | C22: 45664 | D22: 星期二 | E22: 鸣石量化24号 | G22: 赎回 | H22: 1000000 | I22: 100w元 | J22: 日开
A23: 已操作 | B23: =C23-$B$1 -> -300 | C23: 45667 | D23: 星期五 | E23: 艮岳康柏1号 | G23: 申购 | H23: 1000000 | I23: 100w元 | J23: 日开
A24: 已操作 | B24: =C24-$B$1 -> -294 | C24: 45673 | D24: 星期四 | E24: 鸣石量化24号 | G24: 赎回 | H24: 1000000 | I24: 100w元 | J24: 日开
A25: 已操作 | B25: =C25-$B$1 -> -293 | C25: 45674 | D25: 星期五 | E25: 哲萌龙泉进取2号 | G25: 申购 | H25: 3000000 | I25: 300w元 | J25: 日开
A26: 已操作 | B26: =C26-$B$1 -> -289 | C26: 45678 | D26: 星期二 | E26: 德贝尊享CTA8号 | G26: 申购 | H26: 5000000 | I26: 500w元 | J26: 每周二
A27: 已操作 | B27: =C27-$B$1 -> -288 | C27: 45679 | D27: 星期三 | E27: 锡和骐骥1号 | G27: 申购 | H27: 3200000 | I27: 320w元 | J27: 每周二、三
A28: 已操作 | B28: =C28-$B$1 -> -251 | C28: 45716 | D28: 星期五 | E28: 量游鸿雁8号 | G28: 赎回 | H28: 全部赎回 | I28: 大约101w元
A29: 已操作 | B29: =C29-$B$1 -> -246 | C29: 45721 | D29: 星期三 | E29: 锡和骐骥1号 | G29: 申购 | H29: 1000000 | I29: 100w元 | J29: 每周二、三
A30: 已操作 | B30: =C30-$B$1 -> -239 | C30: 45728 | D30: 星期三 | E30: 特夫郁金香弦理1号 | G30: 申购 | H30: 3000000 | I30: 300w
A31: 已操作 | B31: =C31-$B$1 -> -239 | C31: 45728 | D31: 星期三 | E31: 锡和骐骥1号 | G31: 申购 | H31: 1400000 | I31: 140w | J31: 每周二、三
A32: 已操作 | B32: =C32-$B$1 -> -239 | C32: 45728 | D32: 星期三 | E32: 鹏华添利宝货币B | F32: 009824.OF | G32: 申购 | H32: 30000 | I32: 3w | K32: 招嬴通
A33: 已操作 | B33: =C33-$B$1 -> -226 | C33: 45741 | D33: 星期二 | E33: 艮岳康柏1号 | G33: 申购 | H33: 1000000 | I33: 100W
A34: 已操作 | B34: =C34-$B$1 -> -225 | C34: 45742 | D34: 星期三 | E34: 交叉智能-量化套利2号 | G34: 申购 | H34: 3000000 | I34: 300w元 | J34: 每周二、三
A35: 已操作 | B35: =C35-$B$1 -> -225 | C35: 45742 | D35: 星期三 | E35: 交叉智能启航 1 号 | G35: 申购 | H35: 3000000 | I35: 300w元 | J35: 每周二、三
A36: 已操作 | B36: =C36-$B$1 -> -219 | C36: 45748 | D36: 星期二 | E36: 德贝尊享CTA8号 | G36: 赎回 | H36: 2000000 | I36: 200w元 | J36: 每周二
A37: 已操作 | B37: =C37-$B$1 -> -217 | C37: 45750 | D37: 星期四 | E37: 鸣石CTA套利1号 | G37: 申购 | H37: 2000000 | I37: 200w元 | J37: 日开
A38: 已操作 | B38: =C38-$B$1 -> -198 | C38: 45769 | D38: 星期二 | E38: 德贝尊享CTA8号 | G38: 赎回 | H38: 3000000 | I38: 全部赎回，大约300w | J38: 每周二
A39: 已操作 | B39: =C39-$B$1 -> -196 | C39: 45771 | D39: 星期四 | E39: 鸣石CTA套利1号 | G39: 申购 | H39: 1500000 | I39: 150w | J39: 日开
A40: 已操作 | B40: =C40-$B$1 -> -191 | C40: 45776 | D40: 星期二 | E40: 锡和骐骥1号 | G40: 申购 | H40: 1500000 | I40: 150w | J40: 每周二、三
...

Sheet 【套利】鸣石量化24号
A1: 1 | B1: 2 | C1: 3 | D1: 4 | E1: 5 | F1: 6 | G1: 7 | H1: 8 | I1: 9 | J1: 10
A2: 估值日期 | B2: 鸣石量化24号 | C2: 周收益率 | D2: 周度超额 | E2: 最大回撤 | F2: 连续负超额周数 | G2: 周度收益率跌幅≥3% | H2: 持有期最大回撤≥5% | I2: 连续负超额4周 | J2: 分红
A3: =IF(子基金及业绩基准周净值!A3="","",子基金及业绩基准周净值!A3) -> 45469 | B3: =IF(A3="","",VLOOKUP($A3,子基金及业绩基准周净值!$A:$F,2)) -> 1.0494
A4: =IF(子基金及业绩基准周净值!A4="","",子基金及业绩基准周净值!A4) -> 45471 | B4: =IF(A4="","",VLOOKUP($A4,子基金及业绩基准周净值!$A:$F,2)) -> 1.051 | C4: =IF(A4="","",(B4-B3)/B3) -> 0.0015246808 | D4: =IF(A4="","",C4-(子基金及业绩基准周净值!AH4/子基金及业绩基准周净值!AH3-1)) -> #DIV/0! | E4: 0 | F4: 0 | G4: =IF(A4="","",IF(C4<-3%,"是","否")) -> 否 | H4: =IF(A4="","",IF(E4>5%,"是","否")) -> 否 | I4: =IF(A4="","",IF(F4>=4,"是","否")) -> 否
A5: =IF(子基金及业绩基准周净值!A5="","",子基金及业绩基准周净值!A5) -> 45478 | B5: =IF(A5="","",VLOOKUP($A5,子基金及业绩基准周净值!$A:$F,2)) -> 1.0518 | C5: =IF(A5="","",(B5-B4)/B4) -> 0.00076117983 | D5: =IF(A5="","",C5-(子基金及业绩基准周净值!AH5/子基金及业绩基准周净值!AH4-1)) -> #DIV/0! | E5: 0 | F5: 1 | G5: =IF(A5="","",IF(C5<-3%,"是","否")) -> 否 | H5: =IF(A5="","",IF(E5>5%,"是","否")) -> 否 | I5: =IF(A5="","",IF(F5>=4,"是","否")) -> 否
A6: =IF(子基金及业绩基准周净值!A6="","",子基金及业绩基准周净值!A6) -> 45485 | B6: =IF(A6="","",VLOOKUP($A6,子基金及业绩基准周净值!$A:$F,2)) -> 1.0527 | C6: =IF(A6="","",(B6-B5)/B5) -> 0.00085567598 | D6: =IF(A6="","",C6-(子基金及业绩基准周净值!AH6/子基金及业绩基准周净值!AH5-1)) -> -0.00031952448 | E6: 0 | F6: 2 | G6: =IF(A6="","",IF(C6<-3%,"是","否")) -> 否 | H6: =IF(A6="","",IF(E6>5%,"是","否")) -> 否 | I6: =IF(A6="","",IF(F6>=4,"是","否")) -> 否
A7: =IF(子基金及业绩基准周净值!A7="","",子基金及业绩基准周净值!A7) -> 45492 | B7: =IF(A7="","",VLOOKUP($A7,子基金及业绩基准周净值!$A:$F,2)) -> 1.0536 | C7: =IF(A7="","",(B7-B6)/B6) -> 0.00085494443 | D7: =IF(A7="","",C7-(子基金及业绩基准周净值!AH7/子基金及业绩基准周净值!AH6-1)) -> 0.0017110464 | E7: 0 | F7: 0 | G7: =IF(A7="","",IF(C7<-3%,"是","否")) -> 否 | H7: =IF(A7="","",IF(E7>5%,"是","否")) -> 否 | I7: =IF(A7="","",IF(F7>=4,"是","否")) -> 否
A8: =IF(子基金及业绩基准周净值!A8="","",子基金及业绩基准周净值!A8) -> 45499 | B8: =IF(A8="","",VLOOKUP($A8,子基金及业绩基准周净值!$A:$F,2)) -> 1.0585 | C8: =IF(A8="","",(B8-B7)/B7) -> 0.0046507213 | D8: =IF(A8="","",C8-(子基金及业绩基准周净值!AH8/子基金及业绩基准周净值!AH7-1)) -> 0.0075845368 | E8: 0 | F8: 0 | G8: =IF(A8="","",IF(C8<-3%,"是","否")) -> 否 | H8: =IF(A8="","",IF(E8>5%,"是","否")) -> 否 | I8: =IF(A8="","",IF(F8>=4,"是","否")) -> 否
A9: =IF(子基金及业绩基准周净值!A9="","",子基金及业绩基准周净值!A9) -> 45506 | B9: =IF(A9="","",VLOOKUP($A9,子基金及业绩基准周净值!$A:$F,2)) -> 1.0615 | C9: =IF(A9="","",(B9-B8)/B8) -> 0.0028341993 | D9: =IF(A9="","",C9-(子基金及业绩基准周净值!AH9/子基金及业绩基准周净值!AH8-1)) -> 0.0027289571 | E9: 0 | F9: 0 | G9: =IF(A9="","",IF(C9<-3%,"是","否")) -> 否 | H9: =IF(A9="","",IF(E9>5%,"是","否")) -> 否 | I9: =IF(A9="","",IF(F9>=4,"是","否")) -> 否
A10: =IF(子基金及业绩基准周净值!A10="","",子基金及业绩基准周净值!A10) -> 45513 | B10: =IF(A10="","",VLOOKUP($A10,子基金及业绩基准周净值!$A:$F,2)) -> 1.0762 | C10: =IF(A10="","",(B10-B9)/B9) -> 0.013848328 | D10: =IF(A10="","",C10-(子基金及业绩基准周净值!AH10/子基金及业绩基准周净值!AH9-1)) -> 0.016149318 | E10: 0 | F10: 0 | G10: =IF(A10="","",IF(C10<-3%,"是","否")) -> 否 | H10: =IF(A10="","",IF(E10>5%,"是","否")) -> 否 | I10: =IF(A10="","",IF(F10>=4,"是","否")) -> 否
A11: =IF(子基金及业绩基准周净值!A11="","",子基金及业绩基准周净值!A11) -> 45520 | B11: =IF(A11="","",VLOOKUP($A11,子基金及业绩基准周净值!$A:$F,2)) -> 1.0767 | C11: =IF(A11="","",(B11-B10)/B10) -> 0.00046459766 | D11: =IF(A11="","",C11-(子基金及业绩基准周净值!AH11/子基金及业绩基准周净值!AH10-1)) -> -0.0030846909 | E11: 0 | F11: 1 | G11: =IF(A11="","",IF(C11<-3%,"是","否")) -> 否 | H11: =IF(A11="","",IF(E11>5%,"是","否")) -> 否 | I11: =IF(A11="","",IF(F11>=4,"是","否")) -> 否
A12: =IF(子基金及业绩基准周净值!A12="","",子基金及业绩基准周净值!A12) -> 45527 | B12: =IF(A12="","",VLOOKUP($A12,子基金及业绩基准周净值!$A:$F,2)) -> 1.0783 | C12: =IF(A12="","",(B12-B11)/B11) -> 0.0014860221 | D12: =IF(A12="","",C12-(子基金及业绩基准周净值!AH12/子基金及业绩基准周净值!AH11-1)) -> 0.0023810377 | E12: 0 | F12: 0 | G12: =IF(A12="","",IF(C12<-3%,"是","否")) -> 否 | H12: =IF(A12="","",IF(E12>5%,"是","否")) -> 否 | I12: =IF(A12="","",IF(F12>=4,"是","否")) -> 否
A13: =IF(子基金及业绩基准周净值!A13="","",子基金及业绩基准周净值!A13) -> 45534 | B13: =IF(A13="","",VLOOKUP($A13,子基金及业绩基准周净值!$A:$F,2)) -> 1.078 | C13: =IF(A13="","",(B13-B12)/B12) -> -0.00027821571 | D13: =IF(A13="","",C13-(子基金及业绩基准周净值!AH13/子基金及业绩基准周净值!AH12-1)) -> -0.0013586304 | E13: 0.00027821571 | F13: 1 | G13: =IF(A13="","",IF(C13<-3%,"是","否")) -> 否 | H13: =IF(A13="","",IF(E13>5%,"是","否")) -> 否 | I13: =IF(A13="","",IF(F13>=4,"是","否")) -> 否
A14: =IF(子基金及业绩基准周净值!A14="","",子基金及业绩基准周净值!A14) -> 45541 | B14: =IF(A14="","",VLOOKUP($A14,子基金及业绩基准周净值!$A:$F,2)) -> 1.0775 | C14: =IF(A14="","",(B14-B13)/B13) -> -0.00046382189 | D14: =IF(A14="","",C14-(子基金及业绩基准周净值!AH14/子基金及业绩基准周净值!AH13-1)) -> 0.00099494147 | E14: 0.00074190856 | F14: 0 | G14: =IF(A14="","",IF(C14<-3%,"是","否")) -> 否 | H14: =IF(A14="","",IF(E14>5%,"是","否")) -> 否 | I14: =IF(A14="","",IF(F14>=4,"是","否")) -> 否
A15: =IF(子基金及业绩基准周净值!A15="","",子基金及业绩基准周净值!A15) -> 45548 | B15: =IF(A15="","",VLOOKUP($A15,子基金及业绩基准周净值!$A:$F,2)) -> 1.0757 | C15: =IF(A15="","",(B15-B14)/B14) -> -0.0016705336 | D15: =IF(A15="","",C15-(子基金及业绩基准周净值!AH15/子基金及业绩基准周净值!AH14-1)) -> 0.0002368195 | E15: 0.0024112028 | F15: 0 | G15: =IF(A15="","",IF(C15<-3%,"是","否")) -> 否 | H15: =IF(A15="","",IF(E15>5%,"是","否")) -> 否 | I15: =IF(A15="","",IF(F15>=4,"是","否")) -> 否
